Workbook

Sheet README
A1: REACTIVE POWER COMPENSATION SIZING TOOL
A3: A standalone Excel version of the reactive power sizing app. Sheets:
A4: 1. Sizing — the calculation chain: grid demand, transformer consumption, losses, inverter sizing, checks.
A5: 2. GridCodes — database of published grid-code reactive requirements; pick one from the dropdown (B1).
A6: 3. InverterPQ — the manufacturer's Q(t)-mode capability table (% of rated kVA per voltage and loading).
A7: 4. Compliance — V-Q at Registered Capacity and P-Q at nominal voltage vs the selected grid code, with charts.
A9: Colour key: yellow = input cells, grey = calculated, green = key results.
A11: Notes:
A12: - Inverter count: leave the manual-count cell blank to auto-size (meets both reactive and delivery needs).
A13: - Reactive capability precedence: capability table (if 'Use table' = Yes) > manual kVAr override > sqrt(S²-P²).
A14: - Compliance dispatches inverters at (grid limit + losses) / count, as in a G99 Type C study.
A15: - Export capability is net of transformer consumption; absorption is aided by it; capacitor bank exports only.
... A18: - This tool is an analytic screening aid, not a substitute for a network load-flow study.

Sheet Sizing
A1: SIZING
A3: PROJECT
A4: Project name | B4: Belvior
A6: STEP 1 — INITIAL SIZING
A7: Grid injection limit / Registered Capacity | B7: 52.8 | C7: MW
A8: Power factor at grid | B8: 0.95 | C8: cos φ
A9: MVA rating of plant | B9: =B7/B8 | C9: MVA
A10: MVAr demand (grid PF) | B10: =SQRT(B9^2-B7^2) | C10: MVAr
A12: STEP 2 — TRANSFORMER REACTIVE CONSUMPTION
A13: Group | B13: Qty | C13: kVA | D13: Z % | E13: Q (kVAr)
A14: TS Block 1 | B14: 3 | C14: 10164 | D14: 9.5 | E14: =IF(COUNT(B14:D14)=3,B14*C14*D14/100,0)
A15: TS Block 2 | B15: 4 | C15: 7260 | D15: 9.5 | E15: =IF(COUNT(B15:D15)=3,B15*C15*D15/100,0)
A16: Auxiliary transformer (MCR) | B16: 1 | C16: 500 | D16: 4.5 | E16: =IF(COUNT(B16:D16)=3,B16*C16*D16/100,0)
E17: =IF(COUNT(B17:D17)=3,B17*C17*D17/100,0)
E18: =IF(COUNT(B18:D18)=3,B18*C18*D18/100,0)
E19: =IF(COUNT(B19:D19)=3,B19*C19*D19/100,0)
A20: Design margin on transformer demand | B20: 10 | C20: %
A21: Transformer demand incl. margin | B21: =SUM(E14:E19)/1000*(1+B20/100) | C21: MVAr
A22: TOTAL REACTIVE DEMAND | B22: =B10+B21 | C22: MVAr
A24: STEP 3 — INTERNAL SYSTEM LOSSES
A25: Loss source | B25: Fraction % | C25: Loss (MW)
A26: AC cable loss | B26: 1 | C26: =B26*$B$7/100
A27: Auxiliary system loss (string inverters) | B27: 1 | C27: =B27*$B$7/100
A28: Transmission line loss | B28: 0.3 | C28: =B28*$B$7/100
A29: Miscellaneous losses | B29: 1 | C29: =B29*$B$7/100
A30: Total system losses | B30: =SUM(C26:C29) | C30: MW
A31: Capacity to be considered | B31: =B7+B30 | C31: MW
A33: STEP 4 — INVERTER CAPABILITY & COMPENSATION
A34: Inverter apparent power | B34: 363 | C34: kVA
A35: PF at inverter level (tip: Goal Seek on B47/B48) | B35: 0.918 | C35: cos φ
A36: Active power / inverter | B36: =B34*B35 | C36: kW
A37: Reactive capability — derived √(S²-P²) | B37: =SQRT(B34^2-B36^2) | C37: kVAr
A38: Reactive capability — manual override (optional) | C38: kVAr
A39: Reactive capability — from InverterPQ table | B39: =InverterPQ!B16 | C39: kVAr
A40: Q per inverter USED | B40: =IF(InverterPQ!B2="Yes",B39,IF(ISNUMBER(B38),B38,B37)) | C40: kVAr
A41: Capacitor bank | B41: 0 | C41: MVAr
A42: Q for inverters (after cap bank) | B42: =MAX(0,B22-B41) | C42: MVAr
A43: Manual inverter count (blank = auto) | C43: nos.
A44: Required inverters — reactive | B44: =IF(B40>0,ROUNDUP(B42*1000/B40,0),0) | C44: nos.
A45: Required inverters — active delivery | B45: =ROUNDUP(B31*1000/B36,0) | C45: nos.
...

Sheet GridCodes
A1: GRID CODE REQUIREMENT DATABASE
A3: Selected grid code: | B3: United Kingdom - ENA G99 / GB Grid Code (Type C/D PPM)
A5: Key | B5: Name | C5: Q/Pmax | D5: PF | E5: pMin % | F5: pFullLag % | G5: Relief | H5: Stub | I5: VFullLo | J5: VFullHi | K5: Asym | L5: VZeroLo | M5: VZeroHi | N5: Notes
A6: gb_g99 | B6: United Kingdom - ENA G99 / GB Grid Code (Type C/D PPM) | C6: 0.329 | D6: 0.95 | E6: 20 | F6: 20 | G6: 1 | H6: 0.05 | I6: 0.95 | J6: 1.05 | K6: 1 | L6: 0.9 | M6: 1.1 | N6: 0.95 lead/lag at RC from 20% output (G99 13.5.5, Fig 13.13/13.14). Asymmetric V-Q; lead relief triangle 20-50% at DNO discretion; ±5% band below 20%.
A7: de_4110 | B7: Germany - VDE-AR-N 4110 (medium voltage) | C7: 0.329 | D7: 0.95 | E7: 20 | F7: 20 | G7: 0 | H7: 0 | I7: 0.95 | J7: 1.05 | K7: 0 | L7: 0.925 | M7: 1.075 | N7: cos φ 0.95 under/overexcited above 20% of installed capacity; control range 0.925-1.075 pu.
A8: de_4120 | B8: Germany - VDE-AR-N 4120 (high voltage) | C8: 0.411 | D8: 0.925 | E8: 20 | F8: 20 | G8: 0 | H8: 0 | I8: 0.95 | J8: 1.05 | K8: 0 | L8: 0.9 | M8: 1.1 | N8: cos φ 0.925 variant (three TSO-selectable variants exist).
A9: us_1547b | B9: USA - IEEE 1547-2018 (Category B) | C9: 0.44 | D9: 0.9 | E9: 20 | F9: 20 | G9: 0 | H9: 0 | I9: 0.95 | J9: 1.05 | K9: 0 | L9: 0.9 | M9: 1.1 | N9: Inject/absorb 44% of nameplate kVA (~0.90 PF at rated); full capability above 20% of rated power.
A10: au_ner | B10: Australia - NER S5.2.5.1 (Automatic access) | C10: 0.395 | D10: 0.93 | E10: 0 | F10: 0 | G10: 0 | H10: 0 | I10: 0.95 | J10: 1.05 | K10: 0 | L10: 0.9 | M10: 1.1 | N10: ±0.395 x rated active power at any output level.
A11: eu_rfg | B11: EU - ENTSO-E RfG (typical Type C/D implementation) | C11: 0.329 | D11: 0.95 | E11: 20 | F11: 50 | G11: 0 | H11: 0 | I11: 0.95 | J11: 1.05 | K11: 0 | L11: 0.9 | M11: 1.1 | N11: Regulation 2016/631 leaves envelopes to each TSO - typical national choice shown.
A12: pf95 | B12: Generic - fixed PF 0.95 lead/lag | C12: 0.329 | D12: 0.95 | E12: 20 | F12: 20 | G12: 0 | H12: 0 | I12: 0.95 | J12: 1.05 | K12: 0 | L12: 0.9 | M12: 1.1 | N12: Fixed PF, full Q above 20% output.
A13: pf90 | B13: Generic - fixed PF 0.90 lead/lag | C13: 0.484 | D13: 0.9 | E13: 20 | F13: 20 | G13: 0 | H13: 0 | I13: 0.95 | J13: 1.05 | K13: 0 | L13: 0.9 | M13: 1.1 | N13: Fixed PF, full Q above 20% output.
A16: Active parameters (looked up from the selected code):
B17: Q/Pmax | C17: PF | D17: pMin % | E17: pFullLag % | F17: Relief | G17: Stub | H17: VFullLo | I17: VFullHi | J17: Asym | K17: VZeroLo | L17: VZeroHi
B18: =INDEX($C$6:$C$13,MATCH($B$3,$B$6:$B$13,0)) | C18: =INDEX($D$6:$D$13,MATCH($B$3,$B$6:$B$13,0)) | D18: =INDEX($E$6:$E$13,MATCH($B$3,$B$6:$B$13,0)) | E18: =INDEX($F$6:$F$13,MATCH($B$3,$B$6:$B$13,0)) | F18: =INDEX($G$6:$G$13,MATCH($B$3,$B$6:$B$13,0)) | G18: =INDEX($H$6:$H$13,MATCH($B$3,$B$6:$B$13,0)) | H18: =INDEX($I$6:$I$13,MATCH($B$3,$B$6:$B$13,0)) | I18: =INDEX($J$6:$J$13,MATCH($B$3,$B$6:$B$13,0)) | J18: =INDEX($K$6:$K$13,MATCH($B$3,$B$6:$B$13,0)) | K18: =INDEX($L$6:$L$13,MATCH($B$3,$B$6:$B$13,0)) | L18: =INDEX($M$6:$M$13,MATCH($B$3,$B$6:$B$13,0))

Sheet InverterPQ
A1: INVERTER P-Q CAPABILITY TABLE
A2: Use capability table for sizing? | B2: Yes
A3: Max reactive power, % of rated kVA. Blank = N/A (operation not permitted). Rows ascending in voltage.
A4: V (pu) \ P (pu) | B4: 0 | C4: 0.1 | D4: 0.2 | E4: 0.3 | F4: 0.4 | G4: 0.5 | H4: 0.6 | I4: 0.7 | J4: 0.8 | K4: 0.9 | L4: 1
A5: 0.85 | B5: 60 | C5: 60 | D5: 60 | E5: 60 | F5: 60 | G5: 60 | H5: 60 | I5: 48.2 | J5: 28.7
A6: 0.9 | B6: 60 | C6: 60 | D6: 60 | E6: 60 | F6: 60 | G6: 60 | H6: 60 | I6: 56.6 | J6: 41.2 | K6: 0
A7: 0.95 | B7: 60 | C7: 60 | D7: 60 | E7: 60 | F7: 60 | G7: 60 | H7: 60 | I7: 60 | J7: 51.2 | K7: 30.4
A8: 1 | B8: 60 | C8: 60 | D8: 60 | E8: 60 | F8: 60 | G8: 60 | H8: 60 | I8: 60 | J8: 60 | K8: 43.6 | L8: 0
A9: 1.05 | B9: 60 | C9: 60 | D9: 60 | E9: 60 | F9: 60 | G9: 60 | H9: 60 | I9: 60 | J9: 60 | K9: 43.6 | L9: 0
A10: 1.1 | B10: 60 | C10: 60 | D10: 60 | E10: 60 | F10: 60 | G10: 60 | H10: 60 | I10: 60 | J10: 60 | K10: 43.6 | L10: 0
A13: Sizing lookup (1.00 Vn row at PF loading):
A14: Loading (= inverter PF) | B14: =Sizing!B35
A15: q% at 1.00 Vn | B15: =IF($B$14>=1,IF(ISNUMBER(INDEX($B$8:$L$8,1,11)),INDEX($B$8:$L$8,1,11),0),IF(NOT(ISNUMBER(INDEX($B$8:$L$8,1,MATCH($B$14,$B$4:$L$4,1)))),0,IF($B$14=INDEX($B$4:$L$4,1,MATCH($B$14,$B$4:$L$4,1)),INDEX($B$8:$L$8,1,MATCH($B$14,$B$4:$L$4,1)),IF(NOT(ISNUMBER(INDEX($B$8:$L$8,1,MATCH($B$14,$B$4:$L$4,1)+1))),0,INDEX($B$8:$L$8,1,MATCH($B$14,$B$4:$L$4,1))+(INDEX($B$8:$L$8,1,MATCH($B$14,$B$4:$L$4,1)+1)-INDEX($B$8:$L$8,1,MATCH($B$14,$B$4:$L$4,1)))*($B$14-INDEX($B$4:$L$4,1,MATCH($B$14,$B$4:$L$4,1)))/(INDEX($B$4:$L$4,1,MATCH($B$14,$B$4:$L$4,1)+1)-INDEX($B$4:$L$4,1,MATCH($B$14,$B$4:$L$4,1)))))))
A16: q (kVAr) at 1.00 Vn | B16: =B15/100*Sizing!B34

Sheet Compliance
A1: GRID CODE COMPLIANCE
A3: OPERATING POINT (Registered Capacity dispatch)
A4: Dispatch / inverter | I4: =Sizing!B31*1000/Sizing!B46 | J4: kW
A5: Dispatch loading | I5: =I4/Sizing!B34 | J5: pu
A6: Qmax required | I6: =GridCodes!B18*Sizing!B7 | J6: MVAr
A8: CAPABILITY AT TABLE VOLTAGES (per-inverter q% at dispatch loading)
A9: V (pu) | B9: q%/inv | M9: Req polygon Q | N9: V
A10: =InverterPQ!A5 | B10: =IF($I$5>=1,IF(ISNUMBER(INDEX(InverterPQ!$B$5:$L$5,1,11)),INDEX(InverterPQ!$B$5:$L$5,1,11),0),IF(NOT(ISNUMBER(INDEX(InverterPQ!$B$5:$L$5,1,MATCH($I$5,InverterPQ!$B$4:$L$4,1)))),0,IF($I$5=INDEX(InverterPQ!$B$4:$L$4,1,MATCH($I$5,InverterPQ!$B$4:$L$4,1)),INDEX(InverterPQ!$B$5:$L$5,1,MATCH($I$5,InverterPQ!$B$4:$L$4,1)),IF(NOT(ISNUMBER(INDEX(InverterPQ!$B$5:$L$5,1,MATCH($I$5,InverterPQ!$B$4:$L$4,1)+1))),0,INDEX(InverterPQ!$B$5:$L$5,1,MATCH($I$5,InverterPQ!$B$4:$L$4,1))+(INDEX(InverterPQ!$B$5:$L$5,1,MATCH($I$5,InverterPQ!$B$4:$L$4,1)+1)-INDEX(InverterPQ!$B$5:$L$5,1,MATCH($I$5,InverterPQ!$B$4:$L$4,1)))*($I$5-INDEX(InverterPQ!$B$4:$L$4,1,MATCH($I$5,InverterPQ!$B$4:$L$4,1)))/(INDEX(InverterPQ!$B$4:$L$4,1,MATCH($I$5,InverterPQ!$B$4:$L$4,1)+1)-INDEX(InverterPQ!$B$4:$L$4,1,MATCH($I$5,InverterPQ!$B$4:$L$4,1))))))) | M10: =0 | N10: =IF(GridCodes!$J$18=1,GridCodes!$H$18,GridCodes!$K$18)
A11: =InverterPQ!A6 | B11: =IF($I$5>=1,IF(ISNUMBER(INDEX(InverterPQ!$B$6:$L$6,1,11)),INDEX(InverterPQ!$B$6:$L$6,1,11),0),IF(NOT(ISNUMBER(INDEX(InverterPQ!$B$6:$L$6,1,MATCH($I$5,InverterPQ!$B$4:$L$4,1)))),0,IF($I$5=INDEX(InverterPQ!$B$4:$L$4,1,MATCH($I$5,InverterPQ!$B$4:$L$4,1)),INDEX(InverterPQ!$B$6:$L$6,1,MATCH($I$5,InverterPQ!$B$4:$L$4,1)),IF(NOT(ISNUMBER(INDEX(InverterPQ!$B$6:$L$6,1,MATCH($I$5,InverterPQ!$B$4:$L$4,1)+1))),0,INDEX(InverterPQ!$B$6:$L$6,1,MATCH($I$5,InverterPQ!$B$4:$L$4,1))+(INDEX(InverterPQ!$B$6:$L$6,1,MATCH($I$5,InverterPQ!$B$4:$L$4,1)+1)-INDEX(InverterPQ!$B$6:$L$6,1,MATCH($I$5,InverterPQ!$B$4:$L$4,1)))*($I$5-INDEX(InverterPQ!$B$4:$L$4,1,MATCH($I$5,InverterPQ!$B$4:$L$4,1)))/(INDEX(InverterPQ!$B$4:$L$4,1,MATCH($I$5,InverterPQ!$B$4:$L$4,1)+1)-INDEX(InverterPQ!$B$4:$L$4,1,MATCH($I$5,InverterPQ!$B$4:$L$4,1))))))) | M11: =$I$6 | N11: =GridCodes!$H$18
A12: =InverterPQ!A7 | B12: =IF($I$5>=1,IF(ISNUMBER(INDEX(InverterPQ!$B$7:$L$7,1,11)),INDEX(InverterPQ!$B$7:$L$7,1,11),0),IF(NOT(ISNUMBER(INDEX(InverterPQ!$B$7:$L$7,1,MATCH($I$5,InverterPQ!$B$4:$L$4,1)))),0,IF($I$5=INDEX(InverterPQ!$B$4:$L$4,1,MATCH($I$5,InverterPQ!$B$4:$L$4,1)),INDEX(InverterPQ!$B$7:$L$7,1,MATCH($I$5,InverterPQ!$B$4:$L$4,1)),IF(NOT(ISNUMBER(INDEX(InverterPQ!$B$7:$L$7,1,MATCH($I$5,InverterPQ!$B$4:$L$4,1)+1))),0,INDEX(InverterPQ!$B$7:$L$7,1,MATCH($I$5,InverterPQ!$B$4:$L$4,1))+(INDEX(InverterPQ!$B$7:$L$7,1,MATCH($I$5,InverterPQ!$B$4:$L$4,1)+1)-INDEX(InverterPQ!$B$7:$L$7,1,MATCH($I$5,InverterPQ!$B$4:$L$4,1)))*($I$5-INDEX(InverterPQ!$B$4:$L$4,1,MATCH($I$5,InverterPQ!$B$4:$L$4,1)))/(INDEX(InverterPQ!$B$4:$L$4,1,MATCH($I$5,InverterPQ!$B$4:$L$4,1)+1)-INDEX(InverterPQ!$B$4:$L$4,1,MATCH($I$5,InverterPQ!$B$4:$L$4,1))))))) | M12: =$I$6 | N12: =IF(GridCodes!$J$18=1,1,GridCodes!$I$18)
A13: =InverterPQ!A8 | B13: =IF($I$5>=1,IF(ISNUMBER(INDEX(InverterPQ!$B$8:$L$8,1,11)),INDEX(InverterPQ!$B$8:$L$8,1,11),0),IF(NOT(ISNUMBER(INDEX(InverterPQ!$B$8:$L$8,1,MATCH($I$5,InverterPQ!$B$4:$L$4,1)))),0,IF($I$5=INDEX(InverterPQ!$B$4:$L$4,1,MATCH($I$5,InverterPQ!$B$4:$L$4,1)),INDEX(InverterPQ!$B$8:$L$8,1,MATCH($I$5,InverterPQ!$B$4:$L$4,1)),IF(NOT(ISNUMBER(INDEX(InverterPQ!$B$8:$L$8,1,MATCH($I$5,InverterPQ!$B$4:$L$4,1)+1))),0,INDEX(InverterPQ!$B$8:$L$8,1,MATCH($I$5,InverterPQ!$B$4:$L$4,1))+(INDEX(InverterPQ!$B$8:$L$8,1,MATCH($I$5,InverterPQ!$B$4:$L$4,1)+1)-INDEX(InverterPQ!$B$8:$L$8,1,MATCH($I$5,InverterPQ!$B$4:$L$4,1)))*($I$5-INDEX(InverterPQ!$B$4:$L$4,1,MATCH($I$5,InverterPQ!$B$4:$L$4,1)))/(INDEX(InverterPQ!$B$4:$L$4,1,MATCH($I$5,InverterPQ!$B$4:$L$4,1)+1)-INDEX(InverterPQ!$B$4:$L$4,1,MATCH($I$5,InverterPQ!$B$4:$L$4,1))))))) | M13: =0 | N13: =IF(GridCodes!$J$18=1,GridCodes!$I$18,GridCodes!$L$18)
A14: =InverterPQ!A9 | B14: =IF($I$5>=1,IF(ISNUMBER(INDEX(InverterPQ!$B$9:$L$9,1,11)),INDEX(InverterPQ!$B$9:$L$9,1,11),0),IF(NOT(ISNUMBER(INDEX(InverterPQ!$B$9:$L$9,1,MATCH($I$5,InverterPQ!$B$4:$L$4,1)))),0,IF($I$5=INDEX(InverterPQ!$B$4:$L$4,1,MATCH($I$5,InverterPQ!$B$4:$L$4,1)),INDEX(InverterPQ!$B$9:$L$9,1,MATCH($I$5,InverterPQ!$B$4:$L$4,1)),IF(NOT(ISNUMBER(INDEX(InverterPQ!$B$9:$L$9,1,MATCH($I$5,InverterPQ!$B$4:$L$4,1)+1))),0,INDEX(InverterPQ!$B$9:$L$9,1,MATCH($I$5,InverterPQ!$B$4:$L$4,1))+(INDEX(InverterPQ!$B$9:$L$9,1,MATCH($I$5,InverterPQ!$B$4:$L$4,1)+1)-INDEX(InverterPQ!$B$9:$L$9,1,MATCH($I$5,InverterPQ!$B$4:$L$4,1)))*($I$5-INDEX(InverterPQ!$B$4:$L$4,1,MATCH($I$5,InverterPQ!$B$4:$L$4,1)))/(INDEX(InverterPQ!$B$4:$L$4,1,MATCH($I$5,InverterPQ!$B$4:$L$4,1)+1)-INDEX(InverterPQ!$B$4:$L$4,1,MATCH($I$5,InverterPQ!$B$4:$L$4,1))))))) | M14: =-$I$6 | N14: =GridCodes!$I$18
A15: =InverterPQ!A10 | B15: =IF($I$5>=1,IF(ISNUMBER(INDEX(InverterPQ!$B$10:$L$10,1,11)),INDEX(InverterPQ!$B$10:$L$10,1,11),0),IF(NOT(ISNUMBER(INDEX(InverterPQ!$B$10:$L$10,1,MATCH($I$5,InverterPQ!$B$4:$L$4,1)))),0,IF($I$5=INDEX(InverterPQ!$B$4:$L$4,1,MATCH($I$5,InverterPQ!$B$4:$L$4,1)),INDEX(InverterPQ!$B$10:$L$10,1,MATCH($I$5,InverterPQ!$B$4:$L$4,1)),IF(NOT(ISNUMBER(INDEX(InverterPQ!$B$10:$L$10,1,MATCH($I$5,InverterPQ!$B$4:$L$4,1)+1))),0,INDEX(InverterPQ!$B$10:$L$10,1,MATCH($I$5,InverterPQ!$B$4:$L$4,1))+(INDEX(InverterPQ!$B$10:$L$10,1,MATCH($I$5,InverterPQ!$B$4:$L$4,1)+1)-INDEX(InverterPQ!$B$10:$L$10,1,MATCH($I$5,InverterPQ!$B$4:$L$4,1)))*($I$5-INDEX(InverterPQ!$B$4:$L$4,1,MATCH($I$5,InverterPQ!$B$4:$L$4,1)))/(INDEX(InverterPQ!$B$4:$L$4,1,MATCH($I$5,InverterPQ!$B$4:$L$4,1)+1)-INDEX(InverterPQ!$B$4:$L$4,1,MATCH($I$5,InverterPQ!$B$4:$L$4,1))))))) | M15: =-$I$6 | N15: =IF(GridCodes!$J$18=1,1,GridCodes!$H$18)
M16: =0 | N16: =IF(GridCodes!$J$18=1,GridCodes!$H$18,GridCodes!$K$18)
A17: V-Q AT REGISTERED CAPACITY — interpolated sweep and A/B/E/F corner points
A18: Point | B18: V (pu) | C18: j | D18: VA | E18: VB | F18: qA | G18: qB | H18: t | I18: q%/inv | J18: Q prod (MVAr) | K18: Q abs (MVAr) | L18: Req lag (MVAr) | M18: Req lead (MVAr) | N18: -Q abs | O18: Status
B19: 0.85 | C19: =MAX(1,MIN(5,MATCH(B19,$A$10:$A$15,1))) | D19: =INDEX($A$10:$A$15,C19) | E19: =INDEX($A$10:$A$15,C19+1) | F19: =INDEX($B$10:$B$15,C19) | G19: =INDEX($B$10:$B$15,C19+1) | H19: =MIN(1,MAX(0,(B19-D19)/(E19-D19))) | I19: =IF(H19<=0.0001,F19,IF(H19>=0.9999,G19,IF(OR(F19<=0,G19<=0),0,F19+(G19-F19)*H19))) | J19: =Sizing!$B$46*I19/100*Sizing!$B$34/1000+Sizing!$B$41-Sizing!$B$21 | K19: =Sizing!$B$46*I19/100*Sizing!$B$34/1000+Sizing!$B$21 | L19: =$I$6*(IF(GridCodes!$J$18=1,IF(OR(B19<GridCodes!$H$18-0.0001,B19>GridCodes!$I$18+0.0001),0,IF(B19<=1,1,(GridCodes!$I$18-B19)/(GridCodes!$I$18-1))),IF(OR(B19<=GridCodes!$K$18,B19>=GridCodes!$L$18),0,IF(B19<GridCodes!$H$18,(B19-GridCodes!$K$18)/(GridCodes!$H$18-GridCodes!$K$18),IF(B19>GridCodes!$I$18,(GridCodes!$L$18-B19)/(GridCodes!$L$18-GridCodes!$I$18),1))))) | M19: =$I$6*(IF(GridCodes!$J$18=1,IF(OR(B19<GridCodes!$H$18-0.0001,B19>GridCodes!$I$18+0.0001),0,IF(B19>=1,1,(B19-GridCodes!$H$18)/(1-GridCodes!$H$18))),IF(OR(B19<=GridCodes!$K$18,B19>=GridCodes!$L$18),0,IF(B19<GridCodes!$H$18,(B19-GridCodes!$K$18)/(GridCodes!$H$18-GridCodes!$K$18),IF(B19>GridCodes!$I$18,(GridCodes!$L$18-B19)/(GridCodes!$L$18-GridCodes!$I$18),1))))) | N19: =-K19 | O19: =IF(AND(MAX(0,J19)>=L19-0.001,MAX(0,K19)>=M19-0.001),"PASS","FAIL")
B20: 0.8625 | C20: =MAX(1,MIN(5,MATCH(B20,$A$10:$A$15,1))) | D20: =INDEX($A$10:$A$15,C20) | E20: =INDEX($A$10:$A$15,C20+1) | F20: =INDEX($B$10:$B$15,C20) | G20: =INDEX($B$10:$B$15,C20+1) | H20: =MIN(1,MAX(0,(B20-D20)/(E20-D20))) | I20: =IF(H20<=0.0001,F20,IF(H20>=0.9999,G20,IF(OR(F20<=0,G20<=0),0,F20+(G20-F20)*H20))) | J20: =Sizing!$B$46*I20/100*Sizing!$B$34/1000+Sizing!$B$41-Sizing!$B$21 | K20: =Sizing!$B$46*I20/100*Sizing!$B$34/1000+Sizing!$B$21 | L20: =$I$6*(IF(GridCodes!$J$18=1,IF(OR(B20<GridCodes!$H$18-0.0001,B20>GridCodes!$I$18+0.0001),0,IF(B20<=1,1,(GridCodes!$I$18-B20)/(GridCodes!$I$18-1))),IF(OR(B20<=GridCodes!$K$18,B20>=GridCodes!$L$18),0,IF(B20<GridCodes!$H$18,(B20-GridCodes!$K$18)/(GridCodes!$H$18-GridCodes!$K$18),IF(B20>GridCodes!$I$18,(GridCodes!$L$18-B20)/(GridCodes!$L$18-GridCodes!$I$18),1))))) | M20: =$I$6*(IF(GridCodes!$J$18=1,IF(OR(B20<GridCodes!$H$18-0.0001,B20>GridCodes!$I$18+0.0001),0,IF(B20>=1,1,(B20-GridCodes!$H$18)/(1-GridCodes!$H$18))),IF(OR(B20<=GridCodes!$K$18,B20>=GridCodes!$L$18),0,IF(B20<GridCodes!$H$18,(B20-GridCodes!$K$18)/(GridCodes!$H$18-GridCodes!$K$18),IF(B20>GridCodes!$I$18,(GridCodes!$L$18-B20)/(GridCodes!$L$18-GridCodes!$I$18),1))))) | N20: =-K20 | O20: =IF(AND(MAX(0,J20)>=L20-0.001,MAX(0,K20)>=M20-0.001),"PASS","FAIL")
B21: 0.875 | C21: =MAX(1,MIN(5,MATCH(B21,$A$10:$A$15,1))) | D21: =INDEX($A$10:$A$15,C21) | E21: =INDEX($A$10:$A$15,C21+1) | F21: =INDEX($B$10:$B$15,C21) | G21: =INDEX($B$10:$B$15,C21+1) | H21: =MIN(1,MAX(0,(B21-D21)/(E21-D21))) | I21: =IF(H21<=0.0001,F21,IF(H21>=0.9999,G21,IF(OR(F21<=0,G21<=0),0,F21+(G21-F21)*H21))) | J21: =Sizing!$B$46*I21/100*Sizing!$B$34/1000+Sizing!$B$41-Sizing!$B$21 | K21: =Sizing!$B$46*I21/100*Sizing!$B$34/1000+Sizing!$B$21 | L21: =$I$6*(IF(GridCodes!$J$18=1,IF(OR(B21<GridCodes!$H$18-0.0001,B21>GridCodes!$I$18+0.0001),0,IF(B21<=1,1,(GridCodes!$I$18-B21)/(GridCodes!$I$18-1))),IF(OR(B21<=GridCodes!$K$18,B21>=GridCodes!$L$18),0,IF(B21<GridCodes!$H$18,(B21-GridCodes!$K$18)/(GridCodes!$H$18-GridCodes!$K$18),IF(B21>GridCodes!$I$18,(GridCodes!$L$18-B21)/(GridCodes!$L$18-GridCodes!$I$18),1))))) | M21: =$I$6*(IF(GridCodes!$J$18=1,IF(OR(B21<GridCodes!$H$18-0.0001,B21>GridCodes!$I$18+0.0001),0,IF(B21>=1,1,(B21-GridCodes!$H$18)/(1-GridCodes!$H$18))),IF(OR(B21<=GridCodes!$K$18,B21>=GridCodes!$L$18),0,IF(B21<GridCodes!$H$18,(B21-GridCodes!$K$18)/(GridCodes!$H$18-GridCodes!$K$18),IF(B21>GridCodes!$I$18,(GridCodes!$L$18-B21)/(GridCodes!$L$18-GridCodes!$I$18),1))))) | N21: =-K21 | O21: =IF(AND(MAX(0,J21)>=L21-0.001,MAX(0,K21)>=M21-0.001),"PASS","FAIL")
B22: 0.8875 | C22: =MAX(1,MIN(5,MATCH(B22,$A$10:$A$15,1))) | D22: =INDEX($A$10:$A$15,C22) | E22: =INDEX($A$10:$A$15,C22+1) | F22: =INDEX($B$10:$B$15,C22) | G22: =INDEX($B$10:$B$15,C22+1) | H22: =MIN(1,MAX(0,(B22-D22)/(E22-D22))) | I22: =IF(H22<=0.0001,F22,IF(H22>=0.9999,G22,IF(OR(F22<=0,G22<=0),0,F22+(G22-F22)*H22))) | J22: =Sizing!$B$46*I22/100*Sizing!$B$34/1000+Sizing!$B$41-Sizing!$B$21 | K22: =Sizing!$B$46*I22/100*Sizing!$B$34/1000+Sizing!$B$21 | L22: =$I$6*(IF(GridCodes!$J$18=1,IF(OR(B22<GridCodes!$H$18-0.0001,B22>GridCodes!$I$18+0.0001),0,IF(B22<=1,1,(GridCodes!$I$18-B22)/(GridCodes!$I$18-1))),IF(OR(B22<=GridCodes!$K$18,B22>=GridCodes!$L$18),0,IF(B22<GridCodes!$H$18,(B22-GridCodes!$K$18)/(GridCodes!$H$18-GridCodes!$K$18),IF(B22>GridCodes!$I$18,(GridCodes!$L$18-B22)/(GridCodes!$L$18-GridCodes!$I$18),1))))) | M22: =$I$6*(IF(GridCodes!$J$18=1,IF(OR(B22<GridCodes!$H$18-0.0001,B22>GridCodes!$I$18+0.0001),0,IF(B22>=1,1,(B22-GridCodes!$H$18)/(1-GridCodes!$H$18))),IF(OR(B22<=GridCodes!$K$18,B22>=GridCodes!$L$18),0,IF(B22<GridCodes!$H$18,(B22-GridCodes!$K$18)/(GridCodes!$H$18-GridCodes!$K$18),IF(B22>GridCodes!$I$18,(GridCodes!$L$18-B22)/(GridCodes!$L$18-GridCodes!$I$18),1))))) | N22: =-K22 | O22: =IF(AND(MAX(0,J22)>=L22-0.001,MAX(0,K22)>=M22-0.001),"PASS","FAIL")
B23: 0.9 | C23: =MAX(1,MIN(5,MATCH(B23,$A$10:$A$15,1))) | D23: =INDEX($A$10:$A$15,C23) | E23: =INDEX($A$10:$A$15,C23+1) | F23: =INDEX($B$10:$B$15,C23) | G23: =INDEX($B$10:$B$15,C23+1) | H23: =MIN(1,MAX(0,(B23-D23)/(E23-D23))) | I23: =IF(H23<=0.0001,F23,IF(H23>=0.9999,G23,IF(OR(F23<=0,G23<=0),0,F23+(G23-F23)*H23))) | J23: =Sizing!$B$46*I23/100*Sizing!$B$34/1000+Sizing!$B$41-Sizing!$B$21 | K23: =Sizing!$B$46*I23/100*Sizing!$B$34/1000+Sizing!$B$21 | L23: =$I$6*(IF(GridCodes!$J$18=1,IF(OR(B23<GridCodes!$H$18-0.0001,B23>GridCodes!$I$18+0.0001),0,IF(B23<=1,1,(GridCodes!$I$18-B23)/(GridCodes!$I$18-1))),IF(OR(B23<=GridCodes!$K$18,B23>=GridCodes!$L$18),0,IF(B23<GridCodes!$H$18,(B23-GridCodes!$K$18)/(GridCodes!$H$18-GridCodes!$K$18),IF(B23>GridCodes!$I$18,(GridCodes!$L$18-B23)/(GridCodes!$L$18-GridCodes!$I$18),1))))) | M23: =$I$6*(IF(GridCodes!$J$18=1,IF(OR(B23<GridCodes!$H$18-0.0001,B23>GridCodes!$I$18+0.0001),0,IF(B23>=1,1,(B23-GridCodes!$H$18)/(1-GridCodes!$H$18))),IF(OR(B23<=GridCodes!$K$18,B23>=GridCodes!$L$18),0,IF(B23<GridCodes!$H$18,(B23-GridCodes!$K$18)/(GridCodes!$H$18-GridCodes!$K$18),IF(B23>GridCodes!$I$18,(GridCodes!$L$18-B23)/(GridCodes!$L$18-GridCodes!$I$18),1))))) | N23: =-K23 | O23: =IF(AND(MAX(0,J23)>=L23-0.001,MAX(0,K23)>=M23-0.001),"PASS","FAIL")
B24: 0.9125 | C24: =MAX(1,MIN(5,MATCH(B24,$A$10:$A$15,1))) | D24: =INDEX($A$10:$A$15,C24) | E24: =INDEX($A$10:$A$15,C24+1) | F24: =INDEX($B$10:$B$15,C24) | G24: =INDEX($B$10:$B$15,C24+1) | H24: =MIN(1,MAX(0,(B24-D24)/(E24-D24))) | I24: =IF(H24<=0.0001,F24,IF(H24>=0.9999,G24,IF(OR(F24<=0,G24<=0),0,F24+(G24-F24)*H24))) | J24: =Sizing!$B$46*I24/100*Sizing!$B$34/1000+Sizing!$B$41-Sizing!$B$21 | K24: =Sizing!$B$46*I24/100*Sizing!$B$34/1000+Sizing!$B$21 | L24: =$I$6*(IF(GridCodes!$J$18=1,IF(OR(B24<GridCodes!$H$18-0.0001,B24>GridCodes!$I$18+0.0001),0,IF(B24<=1,1,(GridCodes!$I$18-B24)/(GridCodes!$I$18-1))),IF(OR(B24<=GridCodes!$K$18,B24>=GridCodes!$L$18),0,IF(B24<GridCodes!$H$18,(B24-GridCodes!$K$18)/(GridCodes!$H$18-GridCodes!$K$18),IF(B24>GridCodes!$I$18,(GridCodes!$L$18-B24)/(GridCodes!$L$18-GridCodes!$I$18),1))))) | M24: =$I$6*(IF(GridCodes!$J$18=1,IF(OR(B24<GridCodes!$H$18-0.0001,B24>GridCodes!$I$18+0.0001),0,IF(B24>=1,1,(B24-GridCodes!$H$18)/(1-GridCodes!$H$18))),IF(OR(B24<=GridCodes!$K$18,B24>=GridCodes!$L$18),0,IF(B24<GridCodes!$H$18,(B24-GridCodes!$K$18)/(GridCodes!$H$18-GridCodes!$K$18),IF(B24>GridCodes!$I$18,(GridCodes!$L$18-B24)/(GridCodes!$L$18-GridCodes!$I$18),1))))) | N24: =-K24 | O24: =IF(AND(MAX(0,J24)>=L24-0.001,MAX(0,K24)>=M24-0.001),"PASS","FAIL")
B25: 0.925 | C25: =MAX(1,MIN(5,MATCH(B25,$A$10:$A$15,1))) | D25: =INDEX($A$10:$A$15,C25) | E25: =INDEX($A$10:$A$15,C25+1) | F25: =INDEX($B$10:$B$15,C25) | G25: =INDEX($B$10:$B$15,C25+1) | H25: =MIN(1,MAX(0,(B25-D25)/(E25-D25))) | I25: =IF(H25<=0.0001,F25,IF(H25>=0.9999,G25,IF(OR(F25<=0,G25<=0),0,F25+(G25-F25)*H25))) | J25: =Sizing!$B$46*I25/100*Sizing!$B$34/1000+Sizing!$B$41-Sizing!$B$21 | K25: =Sizing!$B$46*I25/100*Sizing!$B$34/1000+Sizing!$B$21 | L25: =$I$6*(IF(GridCodes!$J$18=1,IF(OR(B25<GridCodes!$H$18-0.0001,B25>GridCodes!$I$18+0.0001),0,IF(B25<=1,1,(GridCodes!$I$18-B25)/(GridCodes!$I$18-1))),IF(OR(B25<=GridCodes!$K$18,B25>=GridCodes!$L$18),0,IF(B25<GridCodes!$H$18,(B25-GridCodes!$K$18)/(GridCodes!$H$18-GridCodes!$K$18),IF(B25>GridCodes!$I$18,(GridCodes!$L$18-B25)/(GridCodes!$L$18-GridCodes!$I$18),1))))) | M25: =$I$6*(IF(GridCodes!$J$18=1,IF(OR(B25<GridCodes!$H$18-0.0001,B25>GridCodes!$I$18+0.0001),0,IF(B25>=1,1,(B25-GridCodes!$H$18)/(1-GridCodes!$H$18))),IF(OR(B25<=GridCodes!$K$18,B25>=GridCodes!$L$18),0,IF(B25<GridCodes!$H$18,(B25-GridCodes!$K$18)/(GridCodes!$H$18-GridCodes!$K$18),IF(B25>GridCodes!$I$18,(GridCodes!$L$18-B25)/(GridCodes!$L$18-GridCodes!$I$18),1))))) | N25: =-K25 | O25: =IF(AND(MAX(0,J25)>=L25-0.001,MAX(0,K25)>=M25-0.001),"PASS","FAIL")
B26: 0.9375 | C26: =MAX(1,MIN(5,MATCH(B26,$A$10:$A$15,1))) | D26: =INDEX($A$10:$A$15,C26) | E26: =INDEX($A$10:$A$15,C26+1) | F26: =INDEX($B$10:$B$15,C26) | G26: =INDEX($B$10:$B$15,C26+1) | H26: =MIN(1,MAX(0,(B26-D26)/(E26-D26))) | I26: =IF(H26<=0.0001,F26,IF(H26>=0.9999,G26,IF(OR(F26<=0,G26<=0),0,F26+(G26-F26)*H26))) | J26: =Sizing!$B$46*I26/100*Sizing!$B$34/1000+Sizing!$B$41-Sizing!$B$21 | K26: =Sizing!$B$46*I26/100*Sizing!$B$34/1000+Sizing!$B$21 | L26: =$I$6*(IF(GridCodes!$J$18=1,IF(OR(B26<GridCodes!$H$18-0.0001,B26>GridCodes!$I$18+0.0001),0,IF(B26<=1,1,(GridCodes!$I$18-B26)/(GridCodes!$I$18-1))),IF(OR(B26<=GridCodes!$K$18,B26>=GridCodes!$L$18),0,IF(B26<GridCodes!$H$18,(B26-GridCodes!$K$18)/(GridCodes!$H$18-GridCodes!$K$18),IF(B26>GridCodes!$I$18,(GridCodes!$L$18-B26)/(GridCodes!$L$18-GridCodes!$I$18),1))))) | M26: =$I$6*(IF(GridCodes!$J$18=1,IF(OR(B26<GridCodes!$H$18-0.0001,B26>GridCodes!$I$18+0.0001),0,IF(B26>=1,1,(B26-GridCodes!$H$18)/(1-GridCodes!$H$18))),IF(OR(B26<=GridCodes!$K$18,B26>=GridCodes!$L$18),0,IF(B26<GridCodes!$H$18,(B26-GridCodes!$K$18)/(GridCodes!$H$18-GridCodes!$K$18),IF(B26>GridCodes!$I$18,(GridCodes!$L$18-B26)/(GridCodes!$L$18-GridCodes!$I$18),1))))) | N26: =-K26 | O26: =IF(AND(MAX(0,J26)>=L26-0.001,MAX(0,K26)>=M26-0.001),"PASS","FAIL")
B27: 0.95 | C27: =MAX(1,MIN(5,MATCH(B27,$A$10:$A$15,1))) | D27: =INDEX($A$10:$A$15,C27) | E27: =INDEX($A$10:$A$15,C27+1) | F27: =INDEX($B$10:$B$15,C27) | G27: =INDEX($B$10:$B$15,C27+1) | H27: =MIN(1,MAX(0,(B27-D27)/(E27-D27))) | I27: =IF(H27<=0.0001,F27,IF(H27>=0.9999,G27,IF(OR(F27<=0,G27<=0),0,F27+(G27-F27)*H27))) | J27: =Sizing!$B$46*I27/100*Sizing!$B$34/1000+Sizing!$B$41-Sizing!$B$21 | K27: =Sizing!$B$46*I27/100*Sizing!$B$34/1000+Sizing!$B$21 | L27: =$I$6*(IF(GridCodes!$J$18=1,IF(OR(B27<GridCodes!$H$18-0.0001,B27>GridCodes!$I$18+0.0001),0,IF(B27<=1,1,(GridCodes!$I$18-B27)/(GridCodes!$I$18-1))),IF(OR(B27<=GridCodes!$K$18,B27>=GridCodes!$L$18),0,IF(B27<GridCodes!$H$18,(B27-GridCodes!$K$18)/(GridCodes!$H$18-GridCodes!$K$18),IF(B27>GridCodes!$I$18,(GridCodes!$L$18-B27)/(GridCodes!$L$18-GridCodes!$I$18),1))))) | M27: =$I$6*(IF(GridCodes!$J$18=1,IF(OR(B27<GridCodes!$H$18-0.0001,B27>GridCodes!$I$18+0.0001),0,IF(B27>=1,1,(B27-GridCodes!$H$18)/(1-GridCodes!$H$18))),IF(OR(B27<=GridCodes!$K$18,B27>=GridCodes!$L$18),0,IF(B27<GridCodes!$H$18,(B27-GridCodes!$K$18)/(GridCodes!$H$18-GridCodes!$K$18),IF(B27>GridCodes!$I$18,(GridCodes!$L$18-B27)/(GridCodes!$L$18-GridCodes!$I$18),1))))) | N27: =-K27 | O27: =IF(AND(MAX(0,J27)>=L27-0.001,MAX(0,K27)>=M27-0.001),"PASS","FAIL")
B28: 0.9625 | C28: =MAX(1,MIN(5,MATCH(B28,$A$10:$A$15,1))) | D28: =INDEX($A$10:$A$15,C28) | E28: =INDEX($A$10:$A$15,C28+1) | F28: =INDEX($B$10:$B$15,C28) | G28: =INDEX($B$10:$B$15,C28+1) | H28: =MIN(1,MAX(0,(B28-D28)/(E28-D28))) | I28: =IF(H28<=0.0001,F28,IF(H28>=0.9999,G28,IF(OR(F28<=0,G28<=0),0,F28+(G28-F28)*H28))) | J28: =Sizing!$B$46*I28/100*Sizing!$B$34/1000+Sizing!$B$41-Sizing!$B$21 | K28: =Sizing!$B$46*I28/100*Sizing!$B$34/1000+Sizing!$B$21 | L28: =$I$6*(IF(GridCodes!$J$18=1,IF(OR(B28<GridCodes!$H$18-0.0001,B28>GridCodes!$I$18+0.0001),0,IF(B28<=1,1,(GridCodes!$I$18-B28)/(GridCodes!$I$18-1))),IF(OR(B28<=GridCodes!$K$18,B28>=GridCodes!$L$18),0,IF(B28<GridCodes!$H$18,(B28-GridCodes!$K$18)/(GridCodes!$H$18-GridCodes!$K$18),IF(B28>GridCodes!$I$18,(GridCodes!$L$18-B28)/(GridCodes!$L$18-GridCodes!$I$18),1))))) | M28: =$I$6*(IF(GridCodes!$J$18=1,IF(OR(B28<GridCodes!$H$18-0.0001,B28>GridCodes!$I$18+0.0001),0,IF(B28>=1,1,(B28-GridCodes!$H$18)/(1-GridCodes!$H$18))),IF(OR(B28<=GridCodes!$K$18,B28>=GridCodes!$L$18),0,IF(B28<GridCodes!$H$18,(B28-GridCodes!$K$18)/(GridCodes!$H$18-GridCodes!$K$18),IF(B28>GridCodes!$I$18,(GridCodes!$L$18-B28)/(GridCodes!$L$18-GridCodes!$I$18),1))))) | N28: =-K28 | O28: =IF(AND(MAX(0,J28)>=L28-0.001,MAX(0,K28)>=M28-0.001),"PASS","FAIL")
B29: 0.975 | C29: =MAX(1,MIN(5,MATCH(B29,$A$10:$A$15,1))) | D29: =INDEX($A$10:$A$15,C29) | E29: =INDEX($A$10:$A$15,C29+1) | F29: =INDEX($B$10:$B$15,C29) | G29: =INDEX($B$10:$B$15,C29+1) | H29: =MIN(1,MAX(0,(B29-D29)/(E29-D29))) | I29: =IF(H29<=0.0001,F29,IF(H29>=0.9999,G29,IF(OR(F29<=0,G29<=0),0,F29+(G29-F29)*H29))) | J29: =Sizing!$B$46*I29/100*Sizing!$B$34/1000+Sizing!$B$41-Sizing!$B$21 | K29: =Sizing!$B$46*I29/100*Sizing!$B$34/1000+Sizing!$B$21 | L29: =$I$6*(IF(GridCodes!$J$18=1,IF(OR(B29<GridCodes!$H$18-0.0001,B29>GridCodes!$I$18+0.0001),0,IF(B29<=1,1,(GridCodes!$I$18-B29)/(GridCodes!$I$18-1))),IF(OR(B29<=GridCodes!$K$18,B29>=GridCodes!$L$18),0,IF(B29<GridCodes!$H$18,(B29-GridCodes!$K$18)/(GridCodes!$H$18-GridCodes!$K$18),IF(B29>GridCodes!$I$18,(GridCodes!$L$18-B29)/(GridCodes!$L$18-GridCodes!$I$18),1))))) | M29: =$I$6*(IF(GridCodes!$J$18=1,IF(OR(B29<GridCodes!$H$18-0.0001,B29>GridCodes!$I$18+0.0001),0,IF(B29>=1,1,(B29-GridCodes!$H$18)/(1-GridCodes!$H$18))),IF(OR(B29<=GridCodes!$K$18,B29>=GridCodes!$L$18),0,IF(B29<GridCodes!$H$18,(B29-GridCodes!$K$18)/(GridCodes!$H$18-GridCodes!$K$18),IF(B29>GridCodes!$I$18,(GridCodes!$L$18-B29)/(GridCodes!$L$18-GridCodes!$I$18),1))))) | N29: =-K29 | O29: =IF(AND(MAX(0,J29)>=L29-0.001,MAX(0,K29)>=M29-0.001),"PASS","FAIL")
B30: 0.9875 | C30: =MAX(1,MIN(5,MATCH(B30,$A$10:$A$15,1))) | D30: =INDEX($A$10:$A$15,C30) | E30: =INDEX($A$10:$A$15,C30+1) | F30: =INDEX($B$10:$B$15,C30) | G30: =INDEX($B$10:$B$15,C30+1) | H30: =MIN(1,MAX(0,(B30-D30)/(E30-D30))) | I30: =IF(H30<=0.0001,F30,IF(H30>=0.9999,G30,IF(OR(F30<=0,G30<=0),0,F30+(G30-F30)*H30))) | J30: =Sizing!$B$46*I30/100*Sizing!$B$34/1000+Sizing!$B$41-Sizing!$B$21 | K30: =Sizing!$B$46*I30/100*Sizing!$B$34/1000+Sizing!$B$21 | L30: =$I$6*(IF(GridCodes!$J$18=1,IF(OR(B30<GridCodes!$H$18-0.0001,B30>GridCodes!$I$18+0.0001),0,IF(B30<=1,1,(GridCodes!$I$18-B30)/(GridCodes!$I$18-1))),IF(OR(B30<=GridCodes!$K$18,B30>=GridCodes!$L$18),0,IF(B30<GridCodes!$H$18,(B30-GridCodes!$K$18)/(GridCodes!$H$18-GridCodes!$K$18),IF(B30>GridCodes!$I$18,(GridCodes!$L$18-B30)/(GridCodes!$L$18-GridCodes!$I$18),1))))) | M30: =$I$6*(IF(GridCodes!$J$18=1,IF(OR(B30<GridCodes!$H$18-0.0001,B30>GridCodes!$I$18+0.0001),0,IF(B30>=1,1,(B30-GridCodes!$H$18)/(1-GridCodes!$H$18))),IF(OR(B30<=GridCodes!$K$18,B30>=GridCodes!$L$18),0,IF(B30<GridCodes!$H$18,(B30-GridCodes!$K$18)/(GridCodes!$H$18-GridCodes!$K$18),IF(B30>GridCodes!$I$18,(GridCodes!$L$18-B30)/(GridCodes!$L$18-GridCodes!$I$18),1))))) | N30: =-K30 | O30: =IF(AND(MAX(0,J30)>=L30-0.001,MAX(0,K30)>=M30-0.001),"PASS","FAIL")
... B39: 1.1 | C39: =MAX(1,MIN(5,MATCH(B39,$A$10:$A$15,1))) | D39: =INDEX($A$10:$A$15,C39) | E39: =INDEX($A$10:$A$15,C39+1) | F39: =INDEX($B$10:$B$15,C39) | G39: =INDEX($B$10:$B$15,C39+1) | H39: =MIN(1,MAX(0,(B39-D39)/(E39-D39))) | I39: =IF(H39<=0.0001,F39,IF(H39>=0.9999,G39,IF(OR(F39<=0,G39<=0),0,F39+(G39-F39)*H39))) | J39: =Sizing!$B$46*I39/100*Sizing!$B$34/1000+Sizing!$B$41-Sizing!$B$21 | K39: =Sizing!$B$46*I39/100*Sizing!$B$34/1000+Sizing!$B$21 | L39: =$I$6*(IF(GridCodes!$J$18=1,IF(OR(B39<GridCodes!$H$18-0.0001,B39>GridCodes!$I$18+0.0001),0,IF(B39<=1,1,(GridCodes!$I$18-B39)/(GridCodes!$I$18-1))),IF(OR(B39<=GridCodes!$K$18,B39>=GridCodes!$L$18),0,IF(B39<GridCodes!$H$18,(B39-GridCodes!$K$18)/(GridCodes!$H$18-GridCodes!$K$18),IF(B39>GridCodes!$I$18,(GridCodes!$L$18-B39)/(GridCodes!$L$18-GridCodes!$I$18),1))))) | M39: =$I$6*(IF(GridCodes!$J$18=1,IF(OR(B39<GridCodes!$H$18-0.0001,B39>GridCodes!$I$18+0.0001),0,IF(B39>=1,1,(B39-GridCodes!$H$18)/(1-GridCodes!$H$18))),IF(OR(B39<=GridCodes!$K$18,B39>=GridCodes!$L$18),0,IF(B39<GridCodes!$H$18,(B39-GridCodes!$K$18)/(GridCodes!$H$18-GridCodes!$K$18),IF(B39>GridCodes!$I$18,(GridCodes!$L$18-B39)/(GridCodes!$L$18-GridCodes!$I$18),1))))) | N39: =-K39 | O39: =IF(AND(MAX(0,J39)>=L39-0.001,MAX(0,K39)>=M39-0.001),"PASS","FAIL")
A40: A | B40: =GridCodes!$I$18 | C40: =MAX(1,MIN(5,MATCH(B40,$A$10:$A$15,1))) | D40: =INDEX($A$10:$A$15,C40) | E40: =INDEX($A$10:$A$15,C40+1) | F40: =INDEX($B$10:$B$15,C40) | G40: =INDEX($B$10:$B$15,C40+1) | H40: =MIN(1,MAX(0,(B40-D40)/(E40-D40))) | I40: =IF(H40<=0.0001,F40,IF(H40>=0.9999,G40,IF(OR(F40<=0,G40<=0),0,F40+(G40-F40)*H40))) | J40: =Sizing!$B$46*I40/100*Sizing!$B$34/1000+Sizing!$B$41-Sizing!$B$21 | K40: =Sizing!$B$46*I40/100*Sizing!$B$34/1000+Sizing!$B$21 | L40: =$I$6*(IF(GridCodes!$J$18=1,IF(OR(B40<GridCodes!$H$18-0.0001,B40>GridCodes!$I$18+0.0001),0,IF(B40<=1,1,(GridCodes!$I$18-B40)/(GridCodes!$I$18-1))),IF(OR(B40<=GridCodes!$K$18,B40>=GridCodes!$L$18),0,IF(B40<GridCodes!$H$18,(B40-GridCodes!$K$18)/(GridCodes!$H$18-GridCodes!$K$18),IF(B40>GridCodes!$I$18,(GridCodes!$L$18-B40)/(GridCodes!$L$18-GridCodes!$I$18),1))))) | M40: =$I$6*(IF(GridCodes!$J$18=1,IF(OR(B40<GridCodes!$H$18-0.0001,B40>GridCodes!$I$18+0.0001),0,IF(B40>=1,1,(B40-GridCodes!$H$18)/(1-GridCodes!$H$18))),IF(OR(B40<=GridCodes!$K$18,B40>=GridCodes!$L$18),0,IF(B40<GridCodes!$H$18,(B40-GridCodes!$K$18)/(GridCodes!$H$18-GridCodes!$K$18),IF(B40>GridCodes!$I$18,(GridCodes!$L$18-B40)/(GridCodes!$L$18-GridCodes!$I$18),1))))) | N40: =-K40 | O40: =IF(MAX(0,K40)>=M40-0.001,"PASS","FAIL")
A41: B | B41: =IF(GridCodes!$J$18=1,1,GridCodes!$H$18) | C41: =MAX(1,MIN(5,MATCH(B41,$A$10:$A$15,1))) | D41: =INDEX($A$10:$A$15,C41) | E41: =INDEX($A$10:$A$15,C41+1) | F41: =INDEX($B$10:$B$15,C41) | G41: =INDEX($B$10:$B$15,C41+1) | H41: =MIN(1,MAX(0,(B41-D41)/(E41-D41))) | I41: =IF(H41<=0.0001,F41,IF(H41>=0.9999,G41,IF(OR(F41<=0,G41<=0),0,F41+(G41-F41)*H41))) | J41: =Sizing!$B$46*I41/100*Sizing!$B$34/1000+Sizing!$B$41-Sizing!$B$21 | K41: =Sizing!$B$46*I41/100*Sizing!$B$34/1000+Sizing!$B$21 | L41: =$I$6*(IF(GridCodes!$J$18=1,IF(OR(B41<GridCodes!$H$18-0.0001,B41>GridCodes!$I$18+0.0001),0,IF(B41<=1,1,(GridCodes!$I$18-B41)/(GridCodes!$I$18-1))),IF(OR(B41<=GridCodes!$K$18,B41>=GridCodes!$L$18),0,IF(B41<GridCodes!$H$18,(B41-GridCodes!$K$18)/(GridCodes!$H$18-GridCodes!$K$18),IF(B41>GridCodes!$I$18,(GridCodes!$L$18-B41)/(GridCodes!$L$18-GridCodes!$I$18),1))))) | M41: =$I$6*(IF(GridCodes!$J$18=1,IF(OR(B41<GridCodes!$H$18-0.0001,B41>GridCodes!$I$18+0.0001),0,IF(B41>=1,1,(B41-GridCodes!$H$18)/(1-GridCodes!$H$18))),IF(OR(B41<=GridCodes!$K$18,B41>=GridCodes!$L$18),0,IF(B41<GridCodes!$H$18,(B41-GridCodes!$K$18)/(GridCodes!$H$18-GridCodes!$K$18),IF(B41>GridCodes!$I$18,(GridCodes!$L$18-B41)/(GridCodes!$L$18-GridCodes!$I$18),1))))) | N41: =-K41 | O41: =IF(MAX(0,K41)>=M41-0.001,"PASS","FAIL")
A42: E | B42: =GridCodes!$H$18 | C42: =MAX(1,MIN(5,MATCH(B42,$A$10:$A$15,1))) | D42: =INDEX($A$10:$A$15,C42) | E42: =INDEX($A$10:$A$15,C42+1) | F42: =INDEX($B$10:$B$15,C42) | G42: =INDEX($B$10:$B$15,C42+1) | H42: =MIN(1,MAX(0,(B42-D42)/(E42-D42))) | I42: =IF(H42<=0.0001,F42,IF(H42>=0.9999,G42,IF(OR(F42<=0,G42<=0),0,F42+(G42-F42)*H42))) | J42: =Sizing!$B$46*I42/100*Sizing!$B$34/1000+Sizing!$B$41-Sizing!$B$21 | K42: =Sizing!$B$46*I42/100*Sizing!$B$34/1000+Sizing!$B$21 | L42: =$I$6*(IF(GridCodes!$J$18=1,IF(OR(B42<GridCodes!$H$18-0.0001,B42>GridCodes!$I$18+0.0001),0,IF(B42<=1,1,(GridCodes!$I$18-B42)/(GridCodes!$I$18-1))),IF(OR(B42<=GridCodes!$K$18,B42>=GridCodes!$L$18),0,IF(B42<GridCodes!$H$18,(B42-GridCodes!$K$18)/(GridCodes!$H$18-GridCodes!$K$18),IF(B42>GridCodes!$I$18,(GridCodes!$L$18-B42)/(GridCodes!$L$18-GridCodes!$I$18),1))))) | M42: =$I$6*(IF(GridCodes!$J$18=1,IF(OR(B42<GridCodes!$H$18-0.0001,B42>GridCodes!$I$18+0.0001),0,IF(B42>=1,1,(B42-GridCodes!$H$18)/(1-GridCodes!$H$18))),IF(OR(B42<=GridCodes!$K$18,B42>=GridCodes!$L$18),0,IF(B42<GridCodes!$H$18,(B42-GridCodes!$K$18)/(GridCodes!$H$18-GridCodes!$K$18),IF(B42>GridCodes!$I$18,(GridCodes!$L$18-B42)/(GridCodes!$L$18-GridCodes!$I$18),1))))) | N42: =-K42 | O42: =IF(MAX(0,J42)>=L42-0.001,"PASS","FAIL")
A43: F | B43: =IF(GridCodes!$J$18=1,1,GridCodes!$I$18) | C43: =MAX(1,MIN(5,MATCH(B43,$A$10:$A$15,1))) | D43: =INDEX($A$10:$A$15,C43) | E43: =INDEX($A$10:$A$15,C43+1) | F43: =INDEX($B$10:$B$15,C43) | G43: =INDEX($B$10:$B$15,C43+1) | H43: =MIN(1,MAX(0,(B43-D43)/(E43-D43))) | I43: =IF(H43<=0.0001,F43,IF(H43>=0.9999,G43,IF(OR(F43<=0,G43<=0),0,F43+(G43-F43)*H43))) | J43: =Sizing!$B$46*I43/100*Sizing!$B$34/1000+Sizing!$B$41-Sizing!$B$21 | K43: =Sizing!$B$46*I43/100*Sizing!$B$34/1000+Sizing!$B$21 | L43: =$I$6*(IF(GridCodes!$J$18=1,IF(OR(B43<GridCodes!$H$18-0.0001,B43>GridCodes!$I$18+0.0001),0,IF(B43<=1,1,(GridCodes!$I$18-B43)/(GridCodes!$I$18-1))),IF(OR(B43<=GridCodes!$K$18,B43>=GridCodes!$L$18),0,IF(B43<GridCodes!$H$18,(B43-GridCodes!$K$18)/(GridCodes!$H$18-GridCodes!$K$18),IF(B43>GridCodes!$I$18,(GridCodes!$L$18-B43)/(GridCodes!$L$18-GridCodes!$I$18),1))))) | M43: =$I$6*(IF(GridCodes!$J$18=1,IF(OR(B43<GridCodes!$H$18-0.0001,B43>GridCodes!$I$18+0.0001),0,IF(B43>=1,1,(B43-GridCodes!$H$18)/(1-GridCodes!$H$18))),IF(OR(B43<=GridCodes!$K$18,B43>=GridCodes!$L$18),0,IF(B43<GridCodes!$H$18,(B43-GridCodes!$K$18)/(GridCodes!$H$18-GridCodes!$K$18),IF(B43>GridCodes!$I$18,(GridCodes!$L$18-B43)/(GridCodes!$L$18-GridCodes!$I$18),1))))) | N43: =-K43 | O43: =IF(MAX(0,J43)>=L43-0.001,"PASS","FAIL")
A45: P-Q AT NOMINAL VOLTAGE (1.00 pu)
A46: P (pu) | B46: P (MW) | C46: disp kW | D46: loading | I46: q%/inv | J46: Q prod (MVAr) | K46: Q abs (MVAr) | L46: Req lag (MVAr) | M46: Req lead (MVAr) | N46: -Q abs | O46: Status | P46: -Req lead
A47: 0 | B47: =A47*Sizing!$B$7 | C47: =A47*Sizing!$B$31*1000/Sizing!$B$46 | D47: =C47/Sizing!$B$34 | I47: =IF($D$47>=1,IF(ISNUMBER(INDEX(InverterPQ!$B$8:$L$8,1,11)),INDEX(InverterPQ!$B$8:$L$8,1,11),0),IF(NOT(ISNUMBER(INDEX(InverterPQ!$B$8:$L$8,1,MATCH($D$47,InverterPQ!$B$4:$L$4,1)))),0,IF($D$47=INDEX(InverterPQ!$B$4:$L$4,1,MATCH($D$47,InverterPQ!$B$4:$L$4,1)),INDEX(InverterPQ!$B$8:$L$8,1,MATCH($D$47,InverterPQ!$B$4:$L$4,1)),IF(NOT(ISNUMBER(INDEX(InverterPQ!$B$8:$L$8,1,MATCH($D$47,InverterPQ!$B$4:$L$4,1)+1))),0,INDEX(InverterPQ!$B$8:$L$8,1,MATCH($D$47,InverterPQ!$B$4:$L$4,1))+(INDEX(InverterPQ!$B$8:$L$8,1,MATCH($D$47,InverterPQ!$B$4:$L$4,1)+1)-INDEX(InverterPQ!$B$8:$L$8,1,MATCH($D$47,InverterPQ!$B$4:$L$4,1)))*($D$47-INDEX(InverterPQ!$B$4:$L$4,1,MATCH($D$47,InverterPQ!$B$4:$L$4,1)))/(INDEX(InverterPQ!$B$4:$L$4,1,MATCH($D$47,InverterPQ!$B$4:$L$4,1)+1)-INDEX(InverterPQ!$B$4:$L$4,1,MATCH($D$47,InverterPQ!$B$4:$L$4,1))))))) | J47: =Sizing!$B$46*I47/100*Sizing!$B$34/1000+Sizing!$B$41-Sizing!$B$21 | K47: =Sizing!$B$46*I47/100*Sizing!$B$34/1000+Sizing!$B$21 | L47: =IF(A47<GridCodes!$D$18/100-0.0001,0,$I$6*IF(GridCodes!$E$18<=GridCodes!$D$18,1,MIN(1,(A47-GridCodes!$D$18/100)/(GridCodes!$E$18/100-GridCodes!$D$18/100)))) | M47: =IF(A47<GridCodes!$D$18/100-0.0001,0,IF(GridCodes!$F$18=1,IF(A47>=0.5,$I$6,$I$6*0.12/0.33+($I$6-$I$6*0.12/0.33)*(A47-GridCodes!$D$18/100)/(0.5-GridCodes!$D$18/100)),$I$6*IF(GridCodes!$E$18<=GridCodes!$D$18,1,MIN(1,(A47-GridCodes!$D$18/100)/(GridCodes!$E$18/100-GridCodes!$D$18/100))))) | N47: =-K47 | O47: =IF(AND(MAX(0,J47)>=L47-0.001,MAX(0,K47)>=M47-0.001),"PASS","FAIL") | P47: =-M47
A48: 0.025 | B48: =A48*Sizing!$B$7 | C48: =A48*Sizing!$B$31*1000/Sizing!$B$46 | D48: =C48/Sizing!$B$34 | I48: =IF($D$48>=1,IF(ISNUMBER(INDEX(InverterPQ!$B$8:$L$8,1,11)),INDEX(InverterPQ!$B$8:$L$8,1,11),0),IF(NOT(ISNUMBER(INDEX(InverterPQ!$B$8:$L$8,1,MATCH($D$48,InverterPQ!$B$4:$L$4,1)))),0,IF($D$48=INDEX(InverterPQ!$B$4:$L$4,1,MATCH($D$48,InverterPQ!$B$4:$L$4,1)),INDEX(InverterPQ!$B$8:$L$8,1,MATCH($D$48,InverterPQ!$B$4:$L$4,1)),IF(NOT(ISNUMBER(INDEX(InverterPQ!$B$8:$L$8,1,MATCH($D$48,InverterPQ!$B$4:$L$4,1)+1))),0,INDEX(InverterPQ!$B$8:$L$8,1,MATCH($D$48,InverterPQ!$B$4:$L$4,1))+(INDEX(InverterPQ!$B$8:$L$8,1,MATCH($D$48,InverterPQ!$B$4:$L$4,1)+1)-INDEX(InverterPQ!$B$8:$L$8,1,MATCH($D$48,InverterPQ!$B$4:$L$4,1)))*($D$48-INDEX(InverterPQ!$B$4:$L$4,1,MATCH($D$48,InverterPQ!$B$4:$L$4,1)))/(INDEX(InverterPQ!$B$4:$L$4,1,MATCH($D$48,InverterPQ!$B$4:$L$4,1)+1)-INDEX(InverterPQ!$B$4:$L$4,1,MATCH($D$48,InverterPQ!$B$4:$L$4,1))))))) | J48: =Sizing!$B$46*I48/100*Sizing!$B$34/1000+Sizing!$B$41-Sizing!$B$21 | K48: =Sizing!$B$46*I48/100*Sizing!$B$34/1000+Sizing!$B$21 | L48: =IF(A48<GridCodes!$D$18/100-0.0001,0,$I$6*IF(GridCodes!$E$18<=GridCodes!$D$18,1,MIN(1,(A48-GridCodes!$D$18/100)/(GridCodes!$E$18/100-GridCodes!$D$18/100)))) | M48: =IF(A48<GridCodes!$D$18/100-0.0001,0,IF(GridCodes!$F$18=1,IF(A48>=0.5,$I$6,$I$6*0.12/0.33+($I$6-$I$6*0.12/0.33)*(A48-GridCodes!$D$18/100)/(0.5-GridCodes!$D$18/100)),$I$6*IF(GridCodes!$E$18<=GridCodes!$D$18,1,MIN(1,(A48-GridCodes!$D$18/100)/(GridCodes!$E$18/100-GridCodes!$D$18/100))))) | N48: =-K48 | O48: =IF(AND(MAX(0,J48)>=L48-0.001,MAX(0,K48)>=M48-0.001),"PASS","FAIL") | P48: =-M48
A49: 0.05 | B49: =A49*Sizing!$B$7 | C49: =A49*Sizing!$B$31*1000/Sizing!$B$46 | D49: =C49/Sizing!$B$34 | I49: =IF($D$49>=1,IF(ISNUMBER(INDEX(InverterPQ!$B$8:$L$8,1,11)),INDEX(InverterPQ!$B$8:$L$8,1,11),0),IF(NOT(ISNUMBER(INDEX(InverterPQ!$B$8:$L$8,1,MATCH($D$49,InverterPQ!$B$4:$L$4,1)))),0,IF($D$49=INDEX(InverterPQ!$B$4:$L$4,1,MATCH($D$49,InverterPQ!$B$4:$L$4,1)),INDEX(InverterPQ!$B$8:$L$8,1,MATCH($D$49,InverterPQ!$B$4:$L$4,1)),IF(NOT(ISNUMBER(INDEX(InverterPQ!$B$8:$L$8,1,MATCH($D$49,InverterPQ!$B$4:$L$4,1)+1))),0,INDEX(InverterPQ!$B$8:$L$8,1,MATCH($D$49,InverterPQ!$B$4:$L$4,1))+(INDEX(InverterPQ!$B$8:$L$8,1,MATCH($D$49,InverterPQ!$B$4:$L$4,1)+1)-INDEX(InverterPQ!$B$8:$L$8,1,MATCH($D$49,InverterPQ!$B$4:$L$4,1)))*($D$49-INDEX(InverterPQ!$B$4:$L$4,1,MATCH($D$49,InverterPQ!$B$4:$L$4,1)))/(INDEX(InverterPQ!$B$4:$L$4,1,MATCH($D$49,InverterPQ!$B$4:$L$4,1)+1)-INDEX(InverterPQ!$B$4:$L$4,1,MATCH($D$49,InverterPQ!$B$4:$L$4,1))))))) | J49: =Sizing!$B$46*I49/100*Sizing!$B$34/1000+Sizing!$B$41-Sizing!$B$21 | K49: =Sizing!$B$46*I49/100*Sizing!$B$34/1000+Sizing!$B$21 | L49: =IF(A49<GridCodes!$D$18/100-0.0001,0,$I$6*IF(GridCodes!$E$18<=GridCodes!$D$18,1,MIN(1,(A49-GridCodes!$D$18/100)/(GridCodes!$E$18/100-GridCodes!$D$18/100)))) | M49: =IF(A49<GridCodes!$D$18/100-0.0001,0,IF(GridCodes!$F$18=1,IF(A49>=0.5,$I$6,$I$6*0.12/0.33+($I$6-$I$6*0.12/0.33)*(A49-GridCodes!$D$18/100)/(0.5-GridCodes!$D$18/100)),$I$6*IF(GridCodes!$E$18<=GridCodes!$D$18,1,MIN(1,(A49-GridCodes!$D$18/100)/(GridCodes!$E$18/100-GridCodes!$D$18/100))))) | N49: =-K49 | O49: =IF(AND(MAX(0,J49)>=L49-0.001,MAX(0,K49)>=M49-0.001),"PASS","FAIL") | P49: =-M49
A50: 0.075 | B50: =A50*Sizing!$B$7 | C50: =A50*Sizing!$B$31*1000/Sizing!$B$46 | D50: =C50/Sizing!$B$34 | I50: =IF($D$50>=1,IF(ISNUMBER(INDEX(InverterPQ!$B$8:$L$8,1,11)),INDEX(InverterPQ!$B$8:$L$8,1,11),0),IF(NOT(ISNUMBER(INDEX(InverterPQ!$B$8:$L$8,1,MATCH($D$50,InverterPQ!$B$4:$L$4,1)))),0,IF($D$50=INDEX(InverterPQ!$B$4:$L$4,1,MATCH($D$50,InverterPQ!$B$4:$L$4,1)),INDEX(InverterPQ!$B$8:$L$8,1,MATCH($D$50,InverterPQ!$B$4:$L$4,1)),IF(NOT(ISNUMBER(INDEX(InverterPQ!$B$8:$L$8,1,MATCH($D$50,InverterPQ!$B$4:$L$4,1)+1))),0,INDEX(InverterPQ!$B$8:$L$8,1,MATCH($D$50,InverterPQ!$B$4:$L$4,1))+(INDEX(InverterPQ!$B$8:$L$8,1,MATCH($D$50,InverterPQ!$B$4:$L$4,1)+1)-INDEX(InverterPQ!$B$8:$L$8,1,MATCH($D$50,InverterPQ!$B$4:$L$4,1)))*($D$50-INDEX(InverterPQ!$B$4:$L$4,1,MATCH($D$50,InverterPQ!$B$4:$L$4,1)))/(INDEX(InverterPQ!$B$4:$L$4,1,MATCH($D$50,InverterPQ!$B$4:$L$4,1)+1)-INDEX(InverterPQ!$B$4:$L$4,1,MATCH($D$50,InverterPQ!$B$4:$L$4,1))))))) | J50: =Sizing!$B$46*I50/100*Sizing!$B$34/1000+Sizing!$B$41-Sizing!$B$21 | K50: =Sizing!$B$46*I50/100*Sizing!$B$34/1000+Sizing!$B$21 | L50: =IF(A50<GridCodes!$D$18/100-0.0001,0,$I$6*IF(GridCodes!$E$18<=GridCodes!$D$18,1,MIN(1,(A50-GridCodes!$D$18/100)/(GridCodes!$E$18/100-GridCodes!$D$18/100)))) | M50: =IF(A50<GridCodes!$D$18/100-0.0001,0,IF(GridCodes!$F$18=1,IF(A50>=0.5,$I$6,$I$6*0.12/0.33+($I$6-$I$6*0.12/0.33)*(A50-GridCodes!$D$18/100)/(0.5-GridCodes!$D$18/100)),$I$6*IF(GridCodes!$E$18<=GridCodes!$D$18,1,MIN(1,(A50-GridCodes!$D$18/100)/(GridCodes!$E$18/100-GridCodes!$D$18/100))))) | N50: =-K50 | O50: =IF(AND(MAX(0,J50)>=L50-0.001,MAX(0,K50)>=M50-0.001),"PASS","FAIL") | P50: =-M50
A51: 0.1 | B51: =A51*Sizing!$B$7 | C51: =A51*Sizing!$B$31*1000/Sizing!$B$46 | D51: =C51/Sizing!$B$34 | I51: =IF($D$51>=1,IF(ISNUMBER(INDEX(InverterPQ!$B$8:$L$8,1,11)),INDEX(InverterPQ!$B$8:$L$8,1,11),0),IF(NOT(ISNUMBER(INDEX(InverterPQ!$B$8:$L$8,1,MATCH($D$51,InverterPQ!$B$4:$L$4,1)))),0,IF($D$51=INDEX(InverterPQ!$B$4:$L$4,1,MATCH($D$51,InverterPQ!$B$4:$L$4,1)),INDEX(InverterPQ!$B$8:$L$8,1,MATCH($D$51,InverterPQ!$B$4:$L$4,1)),IF(NOT(ISNUMBER(INDEX(InverterPQ!$B$8:$L$8,1,MATCH($D$51,InverterPQ!$B$4:$L$4,1)+1))),0,INDEX(InverterPQ!$B$8:$L$8,1,MATCH($D$51,InverterPQ!$B$4:$L$4,1))+(INDEX(InverterPQ!$B$8:$L$8,1,MATCH($D$51,InverterPQ!$B$4:$L$4,1)+1)-INDEX(InverterPQ!$B$8:$L$8,1,MATCH($D$51,InverterPQ!$B$4:$L$4,1)))*($D$51-INDEX(InverterPQ!$B$4:$L$4,1,MATCH($D$51,InverterPQ!$B$4:$L$4,1)))/(INDEX(InverterPQ!$B$4:$L$4,1,MATCH($D$51,InverterPQ!$B$4:$L$4,1)+1)-INDEX(InverterPQ!$B$4:$L$4,1,MATCH($D$51,InverterPQ!$B$4:$L$4,1))))))) | J51: =Sizing!$B$46*I51/100*Sizing!$B$34/1000+Sizing!$B$41-Sizing!$B$21 | K51: =Sizing!$B$46*I51/100*Sizing!$B$34/1000+Sizing!$B$21 | L51: =IF(A51<GridCodes!$D$18/100-0.0001,0,$I$6*IF(GridCodes!$E$18<=GridCodes!$D$18,1,MIN(1,(A51-GridCodes!$D$18/100)/(GridCodes!$E$18/100-GridCodes!$D$18/100)))) | M51: =IF(A51<GridCodes!$D$18/100-0.0001,0,IF(GridCodes!$F$18=1,IF(A51>=0.5,$I$6,$I$6*0.12/0.33+($I$6-$I$6*0.12/0.33)*(A51-GridCodes!$D$18/100)/(0.5-GridCodes!$D$18/100)),$I$6*IF(GridCodes!$E$18<=GridCodes!$D$18,1,MIN(1,(A51-GridCodes!$D$18/100)/(GridCodes!$E$18/100-GridCodes!$D$18/100))))) | N51: =-K51 | O51: =IF(AND(MAX(0,J51)>=L51-0.001,MAX(0,K51)>=M51-0.001),"PASS","FAIL") | P51: =-M51
...
