Workbook

Sheet README
A1: REACTIVE POWER COMPENSATION SIZING TOOL
A3: A standalone Excel version of the reactive power sizing app. Sheets:
A4: 1. Sizing — the calculation chain: grid demand, transformer consumption, losses, inverter sizing, checks.
A5: 2. GridCodes — database of published grid-code reactive requirements; pick one from the dropdown.
A6: 3. InverterPQ — the manufacturer's Q(t)-mode capability table (%% of rated kVA per voltage row and loading).
A7: 4. Compliance — V-Q at Registered Capacity and P-Q at nominal voltage vs the selected grid code, with charts.
A9: Colour key: yellow = input cells, grey = calculated, green = key results.
A11: Notes:
A12: - Inverter count: leave the manual-count cell blank to auto-size (meets both reactive and delivery needs).
A13: - Reactive capability precedence: capability table (if 'Use table' = Yes) > manual kVAr override > sqrt(S^2-P^2).
A14: - Compliance dispatches inverters at (grid limit + losses) / count, as in a G99 Type C study.
A15: - Export capability is net of transformer consumption; absorption is aided by it; capacitor bank exports only.
... A17: - This tool is an analytic screening aid, not a substitute for a network load-flow study.

Sheet Sizing
A1: PROJECT
A2: Project name | B2: Belvior
A4: STEP 1 — INITIAL SIZING
A5: Grid injection limit / Registered Capacity | B5: 52.8 | C5: MW
A6: Power factor at grid | B6: 0.95 | C6: cos phi
A7: MVA rating of plant | B7: =B5/B6 -> 55.578947 | C7: MVA
A8: MVAr demand (grid PF) | B8: =SQRT(B7^2-B5^2) -> 17.354521 | C8: MVAr
A10: STEP 2 — TRANSFORMER REACTIVE CONSUMPTION
A11: Group | B11: Qty | C11: Rating (kVA) | D11: Impedance (%) | E11: Q (kVAr)
A12: TS Block 1 | B12: 3 | C12: 10164 | D12: 9.5 | E12: =IF(COUNT(B12:D12)=3,B12*C12*D12/100,0) -> 2896.74
A13: TS Block 2 | B13: 4 | C13: 7260 | D13: 9.5 | E13: =IF(COUNT(B13:D13)=3,B13*C13*D13/100,0) -> 2758.8
A14: Auxiliary transformer (MCR) | B14: 1 | C14: 500 | D14: 4.5 | E14: =IF(COUNT(B14:D14)=3,B14*C14*D14/100,0) -> 22.5
E15: =IF(COUNT(B15:D15)=3,B15*C15*D15/100,0) -> 0
E16: =IF(COUNT(B16:D16)=3,B16*C16*D16/100,0) -> 0
E17: =IF(COUNT(B17:D17)=3,B17*C17*D17/100,0) -> 0
A18: Design margin on transformer demand | B18: 10 | C18: %
A19: Transformer demand incl. margin | B19: =SUM(E12:E17)/1000*(1+B18/100) -> 6.245844 | C19: MVAr
A20: TOTAL REACTIVE DEMAND | B20: =B8+B19 -> 23.600365 | C20: MVAr
A22: STEP 3 — INTERNAL SYSTEM LOSSES
A23: Loss source | B23: Fraction (%) | C23: Loss (MW)
A24: AC cable loss | B24: 1 | C24: =B24*$B$5/100 -> 0.528
A25: Auxiliary system loss (string inverters) | B25: 1 | C25: =B25*$B$5/100 -> 0.528
A26: Transmission line loss | B26: 0.3 | C26: =B26*$B$5/100 -> 0.1584
A27: Miscellaneous losses | B27: 1 | C27: =B27*$B$5/100 -> 0.528
A28: Total system losses | B28: =SUM(C24:C27) -> 1.7424 | C28: MW
A29: Capacity to be considered | B29: =B5+B28 -> 54.5424 | C29: MW
A31: STEP 4 — INVERTER CAPABILITY & COMPENSATION
A32: Inverter apparent power | B32: 363 | C32: kVA
A33: PF at inverter level (use Data > What-If > Goal Seek on B45 or B46) | B33: 0.918 | C33: cos phi
A34: Active power / inverter | B34: =B32*B33 -> 333.234 | C34: kW
A35: Reactive capability - derived sqrt(S^2-P^2) | B35: =SQRT(B32^2-B34^2) -> 143.95868 | C35: kVAr
A36: Reactive capability - manual override (optional) | C36: kVAr
A37: Reactive capability - from InverterPQ table (at PF loading) | B37: =InverterPQ!B16 -> 129.77976 | C37: kVAr
A38: Q per inverter USED | B38: =IF(InverterPQ!B1="Yes",B37,IF(ISNUMBER(B36),B36,B35)) -> 129.77976 | C38: kVAr
A39: Capacitor bank | B39: 0 | C39: MVAr
A40: Q for inverters (after cap bank) | B40: =MAX(0,B20-B39) -> 23.600365 | C40: MVAr
A41: Manual inverter count (blank = auto) | C41: nos.
A42: Required inverters - reactive | B42: =IF(B38>0,ROUNDUP(B40*1000/B38,0),0) -> 182 | C42: nos.
A43: Required inverters - active delivery | B43: =ROUNDUP(B29*1000/B34,0) -> 164 | C43: nos.
A44: Inverters in design | B44: =IF(ISNUMBER(B41),B41,MAX(B42,B43)) -> 182 | C44: nos.
...

Sheet GridCodes
A1: Selected grid code: | B1: United Kingdom - ENA G99 / GB Grid Code (Type C/D PPM)
A3: Key | B3: Name | C3: Q/Pmax | D3: PF | E3: pMin % | F3: pFullLag % | G3: Relief | H3: Stub | I3: VFullLo | J3: VFullHi | K3: Asym | L3: VZeroLo | M3: VZeroHi | N3: Notes
A4: gb_g99 | B4: United Kingdom - ENA G99 / GB Grid Code (Type C/D PPM) | C4: 0.329 | D4: 0.95 | E4: 20 | F4: 20 | G4: 1 | H4: 0.05 | I4: 0.95 | J4: 1.05 | K4: 1 | L4: 0.9 | M4: 1.1 | N4: 0.95 lead/lag at RC from 20% output (G99 13.5.5, Fig 13.13/13.14). Asymmetric V-Q; lead relief triangle 20-50% at DNO discretion; +/-5% band below 20%.
A5: de_4110 | B5: Germany - VDE-AR-N 4110 (medium voltage) | C5: 0.329 | D5: 0.95 | E5: 20 | F5: 20 | G5: 0 | H5: 0 | I5: 0.95 | J5: 1.05 | K5: 0 | L5: 0.925 | M5: 1.075 | N5: cos phi 0.95 under/overexcited above 20% of installed capacity; control range 0.925-1.075 pu.
A6: de_4120 | B6: Germany - VDE-AR-N 4120 (high voltage) | C6: 0.411 | D6: 0.925 | E6: 20 | F6: 20 | G6: 0 | H6: 0 | I6: 0.95 | J6: 1.05 | K6: 0 | L6: 0.9 | M6: 1.1 | N6: cos phi 0.925 variant (three TSO-selectable variants exist).
A7: us_1547b | B7: USA - IEEE 1547-2018 (Category B) | C7: 0.44 | D7: 0.9 | E7: 20 | F7: 20 | G7: 0 | H7: 0 | I7: 0.95 | J7: 1.05 | K7: 0 | L7: 0.9 | M7: 1.1 | N7: Inject/absorb 44% of nameplate kVA (~0.90 PF at rated); full capability above 20% of rated power.
A8: au_ner | B8: Australia - NER S5.2.5.1 (Automatic access) | C8: 0.395 | D8: 0.93 | E8: 0 | F8: 0 | G8: 0 | H8: 0 | I8: 0.95 | J8: 1.05 | K8: 0 | L8: 0.9 | M8: 1.1 | N8: +/-0.395 x rated active power at any output level.
A9: eu_rfg | B9: EU - ENTSO-E RfG (typical Type C/D implementation) | C9: 0.329 | D9: 0.95 | E9: 20 | F9: 50 | G9: 0 | H9: 0 | I9: 0.95 | J9: 1.05 | K9: 0 | L9: 0.9 | M9: 1.1 | N9: Regulation 2016/631 leaves envelopes to each TSO - typical national choice shown.
A10: pf95 | B10: Generic - fixed PF 0.95 lead/lag | C10: 0.329 | D10: 0.95 | E10: 20 | F10: 20 | G10: 0 | H10: 0 | I10: 0.95 | J10: 1.05 | K10: 0 | L10: 0.9 | M10: 1.1 | N10: Fixed PF, full Q above 20% output.
A11: pf90 | B11: Generic - fixed PF 0.90 lead/lag | C11: 0.484 | D11: 0.9 | E11: 20 | F11: 20 | G11: 0 | H11: 0 | I11: 0.95 | J11: 1.05 | K11: 0 | L11: 0.9 | M11: 1.1 | N11: Fixed PF, full Q above 20% output.
A13: Active parameters (looked up from the selected code):
B14: Q/Pmax | C14: PF | D14: pMin % | E14: pFullLag % | F14: Relief | G14: Stub | H14: VFullLo | I14: VFullHi | J14: Asym | K14: VZeroLo | L14: VZeroHi
B15: =INDEX($C$4:$C$11,MATCH($B$1,$B$4:$B$11,0)) -> 0.329 | C15: =INDEX($D$4:$D$11,MATCH($B$1,$B$4:$B$11,0)) -> 0.95 | D15: =INDEX($E$4:$E$11,MATCH($B$1,$B$4:$B$11,0)) -> 20 | E15: =INDEX($F$4:$F$11,MATCH($B$1,$B$4:$B$11,0)) -> 20 | F15: =INDEX($G$4:$G$11,MATCH($B$1,$B$4:$B$11,0)) -> 1 | G15: =INDEX($H$4:$H$11,MATCH($B$1,$B$4:$B$11,0)) -> 0.05 | H15: =INDEX($I$4:$I$11,MATCH($B$1,$B$4:$B$11,0)) -> 0.95 | I15: =INDEX($J$4:$J$11,MATCH($B$1,$B$4:$B$11,0)) -> 1.05 | J15: =INDEX($K$4:$K$11,MATCH($B$1,$B$4:$B$11,0)) -> 1 | K15: =INDEX($L$4:$L$11,MATCH($B$1,$B$4:$B$11,0)) -> 0.9 | L15: =INDEX($M$4:$M$11,MATCH($B$1,$B$4:$B$11,0)) -> 1.1

Sheet InverterPQ
A1: Use capability table for sizing? | B1: Yes
A3: Max reactive power, % of rated kVA (blank = N/A, operation not permitted)
A4: V (pu) \ P loading (pu) | B4: 0 | C4: 0.1 | D4: 0.2 | E4: 0.3 | F4: 0.4 | G4: 0.5 | H4: 0.6 | I4: 0.7 | J4: 0.8 | K4: 0.9 | L4: 1
A5: 1.1 | B5: 60 | C5: 60 | D5: 60 | E5: 60 | F5: 60 | G5: 60 | H5: 60 | I5: 60 | J5: 60 | K5: 43.6 | L5: 0
A6: 1.05 | B6: 60 | C6: 60 | D6: 60 | E6: 60 | F6: 60 | G6: 60 | H6: 60 | I6: 60 | J6: 60 | K6: 43.6 | L6: 0
A7: 1 | B7: 60 | C7: 60 | D7: 60 | E7: 60 | F7: 60 | G7: 60 | H7: 60 | I7: 60 | J7: 60 | K7: 43.6 | L7: 0
A8: 0.95 | B8: 60 | C8: 60 | D8: 60 | E8: 60 | F8: 60 | G8: 60 | H8: 60 | I8: 60 | J8: 51.2 | K8: 30.4
A9: 0.9 | B9: 60 | C9: 60 | D9: 60 | E9: 60 | F9: 60 | G9: 60 | H9: 60 | I9: 56.6 | J9: 41.2 | K9: 0
A10: 0.85 | B10: 60 | C10: 60 | D10: 60 | E10: 60 | F10: 60 | G10: 60 | H10: 60 | I10: 48.2 | J10: 28.7
A13: Sizing lookup (1.00 Vn row at PF loading):
A14: Loading (= inverter PF) | B14: =Sizing!B33 -> 0.918
A15: q% at 1.00 Vn | B15: =IF($B$14>=1,IF(ISNUMBER(INDEX($B$7:$L$7,1,11)),INDEX($B$7:$L$7,1,11),0),IF(OR(NOT(ISNUMBER(INDEX($B$7:$L$7,1,MATCH($B$14,$B$4:$L$4,1))))),0,IF($B$14=INDEX($B$4:$L$4,1,MATCH($B$14,$B$4:$L$4,1)),INDEX($B$7:$L$7,1,MATCH($B$14,$B$4:$L$4,1)),IF(NOT(ISNUMBER(INDEX($B$7:$L$7,1,MATCH($B$14,$B$4:$L$4,1)+1))),0,INDEX($B$7:$L$7,1,MATCH($B$14,$B$4:$L$4,1))+(INDEX($B$7:$L$7,1,MATCH($B$14,$B$4:$L$4,1)+1)-INDEX($B$7:$L$7,1,MATCH($B$14,$B$4:$L$4,1)))*($B$14-INDEX($B$4:$L$4,1,MATCH($B$14,$B$4:$L$4,1)))/(INDEX($B$4:$L$4,1,MATCH($B$14,$B$4:$L$4,1)+1)-INDEX($B$4:$L$4,1,MATCH($B$14,$B$4:$L$4,1))))))) -> 35.752
A16: q (kVAr) at 1.00 Vn | B16: =B15/100*Sizing!B32 -> 129.77976

Sheet Compliance
A1: COMPLIANCE VS SELECTED GRID CODE
A2: Dispatch/inverter | B2: =Sizing!B29*1000/Sizing!B44 -> 299.68352 | C2: kW
A3: Dispatch loading | B3: =B2/Sizing!B32 -> 0.82557443 | C3: pu
A4: Qmax required | B4: =GridCodes!B15*Sizing!B5 -> 17.3712 | C4: MVAr
A6: V-Q AT REGISTERED CAPACITY (table voltages)
A7: V (pu) | B7: q%/inv | C7: Q prod (MVAr) | D7: Q abs (MVAr) | E7: Req lag | F7: Req lead | G7: Status | I7: Req polygon | N7: -Q abs (VQ)
A8: =InverterPQ!A5 -> 1.1 | B8: =IF($B$3>=1,IF(ISNUMBER(INDEX(InverterPQ!$B$5:$L$5,1,11)),INDEX(InverterPQ!$B$5:$L$5,1,11),0),IF(OR(NOT(ISNUMBER(INDEX(InverterPQ!$B$5:$L$5,1,MATCH($B$3,InverterPQ!$B$4:$L$4,1))))),0,IF($B$3=INDEX(InverterPQ!$B$4:$L$4,1,MATCH($B$3,InverterPQ!$B$4:$L$4,1)),INDEX(InverterPQ!$B$5:$L$5,1,MATCH($B$3,InverterPQ!$B$4:$L$4,1)),IF(NOT(ISNUMBER(INDEX(InverterPQ!$B$5:$L$5,1,MATCH($B$3,InverterPQ!$B$4:$L$4,1)+1))),0,INDEX(InverterPQ!$B$5:$L$5,1,MATCH($B$3,InverterPQ!$B$4:$L$4,1))+(INDEX(InverterPQ!$B$5:$L$5,1,MATCH($B$3,InverterPQ!$B$4:$L$4,1)+1)-INDEX(InverterPQ!$B$5:$L$5,1,MATCH($B$3,InverterPQ!$B$4:$L$4,1)))*($B$3-INDEX(InverterPQ!$B$4:$L$4,1,MATCH($B$3,InverterPQ!$B$4:$L$4,1)))/(INDEX(InverterPQ!$B$4:$L$4,1,MATCH($B$3,InverterPQ!$B$4:$L$4,1)+1)-INDEX(InverterPQ!$B$4:$L$4,1,MATCH($B$3,InverterPQ!$B$4:$L$4,1))))))) -> 55.805794 | C8: =Sizing!$B$44*B8/100*Sizing!$B$32/1000+Sizing!$B$39-Sizing!$B$19 -> 30.622812 | D8: =Sizing!$B$44*B8/100*Sizing!$B$32/1000+Sizing!$B$19 -> 43.1145 | E8: =$B$4*(IF(GridCodes!$J$15=1,IF(OR(A8<GridCodes!$H$15-0.0001,A8>GridCodes!$I$15+0.0001),0,IF(A8<=1,1,(GridCodes!$I$15-A8)/(GridCodes!$I$15-1))),IF(OR(A8<=GridCodes!$K$15,A8>=GridCodes!$L$15),0,IF(A8<GridCodes!$H$15,(A8-GridCodes!$K$15)/(GridCodes!$H$15-GridCodes!$K$15),IF(A8>GridCodes!$I$15,(GridCodes!$L$15-A8)/(GridCodes!$L$15-GridCodes!$I$15),1))))) -> 0 | F8: =$B$4*(IF(GridCodes!$J$15=1,IF(OR(A8<GridCodes!$H$15-0.0001,A8>GridCodes!$I$15+0.0001),0,IF(A8>=1,1,(A8-GridCodes!$H$15)/(1-GridCodes!$H$15))),IF(OR(A8<=GridCodes!$K$15,A8>=GridCodes!$L$15),0,IF(A8<GridCodes!$H$15,(A8-GridCodes!$K$15)/(GridCodes!$H$15-GridCodes!$K$15),IF(A8>GridCodes!$I$15,(GridCodes!$L$15-A8)/(GridCodes!$L$15-GridCodes!$I$15),1))))) -> 0 | G8: =IF(AND(MAX(0,C8)>=E8-0.001,MAX(0,D8)>=F8-0.001),"PASS","FAIL") -> PASS | I8: Q | J8: V | N8: =-D8 -> -43.1145
A9: =InverterPQ!A6 -> 1.05 | B9: =IF($B$3>=1,IF(ISNUMBER(INDEX(InverterPQ!$B$6:$L$6,1,11)),INDEX(InverterPQ!$B$6:$L$6,1,11),0),IF(OR(NOT(ISNUMBER(INDEX(InverterPQ!$B$6:$L$6,1,MATCH($B$3,InverterPQ!$B$4:$L$4,1))))),0,IF($B$3=INDEX(InverterPQ!$B$4:$L$4,1,MATCH($B$3,InverterPQ!$B$4:$L$4,1)),INDEX(InverterPQ!$B$6:$L$6,1,MATCH($B$3,InverterPQ!$B$4:$L$4,1)),IF(NOT(ISNUMBER(INDEX(InverterPQ!$B$6:$L$6,1,MATCH($B$3,InverterPQ!$B$4:$L$4,1)+1))),0,INDEX(InverterPQ!$B$6:$L$6,1,MATCH($B$3,InverterPQ!$B$4:$L$4,1))+(INDEX(InverterPQ!$B$6:$L$6,1,MATCH($B$3,InverterPQ!$B$4:$L$4,1)+1)-INDEX(InverterPQ!$B$6:$L$6,1,MATCH($B$3,InverterPQ!$B$4:$L$4,1)))*($B$3-INDEX(InverterPQ!$B$4:$L$4,1,MATCH($B$3,InverterPQ!$B$4:$L$4,1)))/(INDEX(InverterPQ!$B$4:$L$4,1,MATCH($B$3,InverterPQ!$B$4:$L$4,1)+1)-INDEX(InverterPQ!$B$4:$L$4,1,MATCH($B$3,InverterPQ!$B$4:$L$4,1))))))) -> 55.805794 | C9: =Sizing!$B$44*B9/100*Sizing!$B$32/1000+Sizing!$B$39-Sizing!$B$19 -> 30.622812 | D9: =Sizing!$B$44*B9/100*Sizing!$B$32/1000+Sizing!$B$19 -> 43.1145 | E9: =$B$4*(IF(GridCodes!$J$15=1,IF(OR(A9<GridCodes!$H$15-0.0001,A9>GridCodes!$I$15+0.0001),0,IF(A9<=1,1,(GridCodes!$I$15-A9)/(GridCodes!$I$15-1))),IF(OR(A9<=GridCodes!$K$15,A9>=GridCodes!$L$15),0,IF(A9<GridCodes!$H$15,(A9-GridCodes!$K$15)/(GridCodes!$H$15-GridCodes!$K$15),IF(A9>GridCodes!$I$15,(GridCodes!$L$15-A9)/(GridCodes!$L$15-GridCodes!$I$15),1))))) -> 0 | F9: =$B$4*(IF(GridCodes!$J$15=1,IF(OR(A9<GridCodes!$H$15-0.0001,A9>GridCodes!$I$15+0.0001),0,IF(A9>=1,1,(A9-GridCodes!$H$15)/(1-GridCodes!$H$15))),IF(OR(A9<=GridCodes!$K$15,A9>=GridCodes!$L$15),0,IF(A9<GridCodes!$H$15,(A9-GridCodes!$K$15)/(GridCodes!$H$15-GridCodes!$K$15),IF(A9>GridCodes!$I$15,(GridCodes!$L$15-A9)/(GridCodes!$L$15-GridCodes!$I$15),1))))) -> 17.3712 | G9: =IF(AND(MAX(0,C9)>=E9-0.001,MAX(0,D9)>=F9-0.001),"PASS","FAIL") -> PASS | I9: =0 -> 0 | J9: =IF(GridCodes!$J$15=1,GridCodes!$H$15,GridCodes!$K$15) -> 0.95 | N9: =-D9 -> -43.1145
A10: =InverterPQ!A7 -> 1 | B10: =IF($B$3>=1,IF(ISNUMBER(INDEX(InverterPQ!$B$7:$L$7,1,11)),INDEX(InverterPQ!$B$7:$L$7,1,11),0),IF(OR(NOT(ISNUMBER(INDEX(InverterPQ!$B$7:$L$7,1,MATCH($B$3,InverterPQ!$B$4:$L$4,1))))),0,IF($B$3=INDEX(InverterPQ!$B$4:$L$4,1,MATCH($B$3,InverterPQ!$B$4:$L$4,1)),INDEX(InverterPQ!$B$7:$L$7,1,MATCH($B$3,InverterPQ!$B$4:$L$4,1)),IF(NOT(ISNUMBER(INDEX(InverterPQ!$B$7:$L$7,1,MATCH($B$3,InverterPQ!$B$4:$L$4,1)+1))),0,INDEX(InverterPQ!$B$7:$L$7,1,MATCH($B$3,InverterPQ!$B$4:$L$4,1))+(INDEX(InverterPQ!$B$7:$L$7,1,MATCH($B$3,InverterPQ!$B$4:$L$4,1)+1)-INDEX(InverterPQ!$B$7:$L$7,1,MATCH($B$3,InverterPQ!$B$4:$L$4,1)))*($B$3-INDEX(InverterPQ!$B$4:$L$4,1,MATCH($B$3,InverterPQ!$B$4:$L$4,1)))/(INDEX(InverterPQ!$B$4:$L$4,1,MATCH($B$3,InverterPQ!$B$4:$L$4,1)+1)-INDEX(InverterPQ!$B$4:$L$4,1,MATCH($B$3,InverterPQ!$B$4:$L$4,1))))))) -> 55.805794 | C10: =Sizing!$B$44*B10/100*Sizing!$B$32/1000+Sizing!$B$39-Sizing!$B$19 -> 30.622812 | D10: =Sizing!$B$44*B10/100*Sizing!$B$32/1000+Sizing!$B$19 -> 43.1145 | E10: =$B$4*(IF(GridCodes!$J$15=1,IF(OR(A10<GridCodes!$H$15-0.0001,A10>GridCodes!$I$15+0.0001),0,IF(A10<=1,1,(GridCodes!$I$15-A10)/(GridCodes!$I$15-1))),IF(OR(A10<=GridCodes!$K$15,A10>=GridCodes!$L$15),0,IF(A10<GridCodes!$H$15,(A10-GridCodes!$K$15)/(GridCodes!$H$15-GridCodes!$K$15),IF(A10>GridCodes!$I$15,(GridCodes!$L$15-A10)/(GridCodes!$L$15-GridCodes!$I$15),1))))) -> 17.3712 | F10: =$B$4*(IF(GridCodes!$J$15=1,IF(OR(A10<GridCodes!$H$15-0.0001,A10>GridCodes!$I$15+0.0001),0,IF(A10>=1,1,(A10-GridCodes!$H$15)/(1-GridCodes!$H$15))),IF(OR(A10<=GridCodes!$K$15,A10>=GridCodes!$L$15),0,IF(A10<GridCodes!$H$15,(A10-GridCodes!$K$15)/(GridCodes!$H$15-GridCodes!$K$15),IF(A10>GridCodes!$I$15,(GridCodes!$L$15-A10)/(GridCodes!$L$15-GridCodes!$I$15),1))))) -> 17.3712 | G10: =IF(AND(MAX(0,C10)>=E10-0.001,MAX(0,D10)>=F10-0.001),"PASS","FAIL") -> PASS | I10: =$B$4 -> 17.3712 | J10: =GridCodes!$H$15 -> 0.95 | N10: =-D10 -> -43.1145
A11: =InverterPQ!A8 -> 0.95 | B11: =IF($B$3>=1,IF(ISNUMBER(INDEX(InverterPQ!$B$8:$L$8,1,11)),INDEX(InverterPQ!$B$8:$L$8,1,11),0),IF(OR(NOT(ISNUMBER(INDEX(InverterPQ!$B$8:$L$8,1,MATCH($B$3,InverterPQ!$B$4:$L$4,1))))),0,IF($B$3=INDEX(InverterPQ!$B$4:$L$4,1,MATCH($B$3,InverterPQ!$B$4:$L$4,1)),INDEX(InverterPQ!$B$8:$L$8,1,MATCH($B$3,InverterPQ!$B$4:$L$4,1)),IF(NOT(ISNUMBER(INDEX(InverterPQ!$B$8:$L$8,1,MATCH($B$3,InverterPQ!$B$4:$L$4,1)+1))),0,INDEX(InverterPQ!$B$8:$L$8,1,MATCH($B$3,InverterPQ!$B$4:$L$4,1))+(INDEX(InverterPQ!$B$8:$L$8,1,MATCH($B$3,InverterPQ!$B$4:$L$4,1)+1)-INDEX(InverterPQ!$B$8:$L$8,1,MATCH($B$3,InverterPQ!$B$4:$L$4,1)))*($B$3-INDEX(InverterPQ!$B$4:$L$4,1,MATCH($B$3,InverterPQ!$B$4:$L$4,1)))/(INDEX(InverterPQ!$B$4:$L$4,1,MATCH($B$3,InverterPQ!$B$4:$L$4,1)+1)-INDEX(InverterPQ!$B$4:$L$4,1,MATCH($B$3,InverterPQ!$B$4:$L$4,1))))))) -> 45.880519 | C11: =Sizing!$B$44*B11/100*Sizing!$B$32/1000+Sizing!$B$39-Sizing!$B$19 -> 24.06558 | D11: =Sizing!$B$44*B11/100*Sizing!$B$32/1000+Sizing!$B$19 -> 36.557268 | E11: =$B$4*(IF(GridCodes!$J$15=1,IF(OR(A11<GridCodes!$H$15-0.0001,A11>GridCodes!$I$15+0.0001),0,IF(A11<=1,1,(GridCodes!$I$15-A11)/(GridCodes!$I$15-1))),IF(OR(A11<=GridCodes!$K$15,A11>=GridCodes!$L$15),0,IF(A11<GridCodes!$H$15,(A11-GridCodes!$K$15)/(GridCodes!$H$15-GridCodes!$K$15),IF(A11>GridCodes!$I$15,(GridCodes!$L$15-A11)/(GridCodes!$L$15-GridCodes!$I$15),1))))) -> 17.3712 | F11: =$B$4*(IF(GridCodes!$J$15=1,IF(OR(A11<GridCodes!$H$15-0.0001,A11>GridCodes!$I$15+0.0001),0,IF(A11>=1,1,(A11-GridCodes!$H$15)/(1-GridCodes!$H$15))),IF(OR(A11<=GridCodes!$K$15,A11>=GridCodes!$L$15),0,IF(A11<GridCodes!$H$15,(A11-GridCodes!$K$15)/(GridCodes!$H$15-GridCodes!$K$15),IF(A11>GridCodes!$I$15,(GridCodes!$L$15-A11)/(GridCodes!$L$15-GridCodes!$I$15),1))))) -> 0 | G11: =IF(AND(MAX(0,C11)>=E11-0.001,MAX(0,D11)>=F11-0.001),"PASS","FAIL") -> PASS | I11: =$B$4 -> 17.3712 | J11: =IF(GridCodes!$J$15=1,1,GridCodes!$I$15) -> 1 | N11: =-D11 -> -36.557268
A12: =InverterPQ!A9 -> 0.9 | B12: =IF($B$3>=1,IF(ISNUMBER(INDEX(InverterPQ!$B$9:$L$9,1,11)),INDEX(InverterPQ!$B$9:$L$9,1,11),0),IF(OR(NOT(ISNUMBER(INDEX(InverterPQ!$B$9:$L$9,1,MATCH($B$3,InverterPQ!$B$4:$L$4,1))))),0,IF($B$3=INDEX(InverterPQ!$B$4:$L$4,1,MATCH($B$3,InverterPQ!$B$4:$L$4,1)),INDEX(InverterPQ!$B$9:$L$9,1,MATCH($B$3,InverterPQ!$B$4:$L$4,1)),IF(NOT(ISNUMBER(INDEX(InverterPQ!$B$9:$L$9,1,MATCH($B$3,InverterPQ!$B$4:$L$4,1)+1))),0,INDEX(InverterPQ!$B$9:$L$9,1,MATCH($B$3,InverterPQ!$B$4:$L$4,1))+(INDEX(InverterPQ!$B$9:$L$9,1,MATCH($B$3,InverterPQ!$B$4:$L$4,1)+1)-INDEX(InverterPQ!$B$9:$L$9,1,MATCH($B$3,InverterPQ!$B$4:$L$4,1)))*($B$3-INDEX(InverterPQ!$B$4:$L$4,1,MATCH($B$3,InverterPQ!$B$4:$L$4,1)))/(INDEX(InverterPQ!$B$4:$L$4,1,MATCH($B$3,InverterPQ!$B$4:$L$4,1)+1)-INDEX(InverterPQ!$B$4:$L$4,1,MATCH($B$3,InverterPQ!$B$4:$L$4,1))))))) -> 30.663337 | C12: =Sizing!$B$44*B12/100*Sizing!$B$32/1000+Sizing!$B$39-Sizing!$B$19 -> 14.012196 | D12: =Sizing!$B$44*B12/100*Sizing!$B$32/1000+Sizing!$B$19 -> 26.503884 | E12: =$B$4*(IF(GridCodes!$J$15=1,IF(OR(A12<GridCodes!$H$15-0.0001,A12>GridCodes!$I$15+0.0001),0,IF(A12<=1,1,(GridCodes!$I$15-A12)/(GridCodes!$I$15-1))),IF(OR(A12<=GridCodes!$K$15,A12>=GridCodes!$L$15),0,IF(A12<GridCodes!$H$15,(A12-GridCodes!$K$15)/(GridCodes!$H$15-GridCodes!$K$15),IF(A12>GridCodes!$I$15,(GridCodes!$L$15-A12)/(GridCodes!$L$15-GridCodes!$I$15),1))))) -> 0 | F12: =$B$4*(IF(GridCodes!$J$15=1,IF(OR(A12<GridCodes!$H$15-0.0001,A12>GridCodes!$I$15+0.0001),0,IF(A12>=1,1,(A12-GridCodes!$H$15)/(1-GridCodes!$H$15))),IF(OR(A12<=GridCodes!$K$15,A12>=GridCodes!$L$15),0,IF(A12<GridCodes!$H$15,(A12-GridCodes!$K$15)/(GridCodes!$H$15-GridCodes!$K$15),IF(A12>GridCodes!$I$15,(GridCodes!$L$15-A12)/(GridCodes!$L$15-GridCodes!$I$15),1))))) -> 0 | G12: =IF(AND(MAX(0,C12)>=E12-0.001,MAX(0,D12)>=F12-0.001),"PASS","FAIL") -> PASS | I12: =0 -> 0 | J12: =IF(GridCodes!$J$15=1,GridCodes!$I$15,GridCodes!$L$15) -> 1.05 | N12: =-D12 -> -26.503884
A13: =InverterPQ!A10 -> 0.85 | B13: =IF($B$3>=1,IF(ISNUMBER(INDEX(InverterPQ!$B$10:$L$10,1,11)),INDEX(InverterPQ!$B$10:$L$10,1,11),0),IF(OR(NOT(ISNUMBER(INDEX(InverterPQ!$B$10:$L$10,1,MATCH($B$3,InverterPQ!$B$4:$L$4,1))))),0,IF($B$3=INDEX(InverterPQ!$B$4:$L$4,1,MATCH($B$3,InverterPQ!$B$4:$L$4,1)),INDEX(InverterPQ!$B$10:$L$10,1,MATCH($B$3,InverterPQ!$B$4:$L$4,1)),IF(NOT(ISNUMBER(INDEX(InverterPQ!$B$10:$L$10,1,MATCH($B$3,InverterPQ!$B$4:$L$4,1)+1))),0,INDEX(InverterPQ!$B$10:$L$10,1,MATCH($B$3,InverterPQ!$B$4:$L$4,1))+(INDEX(InverterPQ!$B$10:$L$10,1,MATCH($B$3,InverterPQ!$B$4:$L$4,1)+1)-INDEX(InverterPQ!$B$10:$L$10,1,MATCH($B$3,InverterPQ!$B$4:$L$4,1)))*($B$3-INDEX(InverterPQ!$B$4:$L$4,1,MATCH($B$3,InverterPQ!$B$4:$L$4,1)))/(INDEX(InverterPQ!$B$4:$L$4,1,MATCH($B$3,InverterPQ!$B$4:$L$4,1)+1)-INDEX(InverterPQ!$B$4:$L$4,1,MATCH($B$3,InverterPQ!$B$4:$L$4,1))))))) -> 0 | C13: =Sizing!$B$44*B13/100*Sizing!$B$32/1000+Sizing!$B$39-Sizing!$B$19 -> -6.245844 | D13: =Sizing!$B$44*B13/100*Sizing!$B$32/1000+Sizing!$B$19 -> 6.245844 | E13: =$B$4*(IF(GridCodes!$J$15=1,IF(OR(A13<GridCodes!$H$15-0.0001,A13>GridCodes!$I$15+0.0001),0,IF(A13<=1,1,(GridCodes!$I$15-A13)/(GridCodes!$I$15-1))),IF(OR(A13<=GridCodes!$K$15,A13>=GridCodes!$L$15),0,IF(A13<GridCodes!$H$15,(A13-GridCodes!$K$15)/(GridCodes!$H$15-GridCodes!$K$15),IF(A13>GridCodes!$I$15,(GridCodes!$L$15-A13)/(GridCodes!$L$15-GridCodes!$I$15),1))))) -> 0 | F13: =$B$4*(IF(GridCodes!$J$15=1,IF(OR(A13<GridCodes!$H$15-0.0001,A13>GridCodes!$I$15+0.0001),0,IF(A13>=1,1,(A13-GridCodes!$H$15)/(1-GridCodes!$H$15))),IF(OR(A13<=GridCodes!$K$15,A13>=GridCodes!$L$15),0,IF(A13<GridCodes!$H$15,(A13-GridCodes!$K$15)/(GridCodes!$H$15-GridCodes!$K$15),IF(A13>GridCodes!$I$15,(GridCodes!$L$15-A13)/(GridCodes!$L$15-GridCodes!$I$15),1))))) -> 0 | G13: =IF(AND(MAX(0,C13)>=E13-0.001,MAX(0,D13)>=F13-0.001),"PASS","FAIL") -> PASS | I13: =-$B$4 -> -17.3712 | J13: =GridCodes!$I$15 -> 1.05 | N13: =-D13 -> -6.245844
I14: =-$B$4 -> -17.3712 | J14: =IF(GridCodes!$J$15=1,1,GridCodes!$H$15) -> 1
I15: =0 -> 0 | J15: =IF(GridCodes!$J$15=1,GridCodes!$H$15,GridCodes!$K$15) -> 0.95
A20: P-Q AT NOMINAL VOLTAGE (1.00 pu)
A21: P (pu) | B21: P (MW) | C21: disp (kW) | D21: loading | E21: q%/inv | F21: Q prod | G21: Q abs | H21: Req lag | I21: Req lead | J21: Status | K21: -Req lead | L21: -Q abs
A22: 0 | B22: =A22*Sizing!$B$5 -> 0 | C22: =A22*Sizing!$B$29*1000/Sizing!$B$44 -> 0 | D22: =C22/Sizing!$B$32 -> 0 | E22: =IF($D$22>=1,IF(ISNUMBER(INDEX(InverterPQ!$B$7:$L$7,1,11)),INDEX(InverterPQ!$B$7:$L$7,1,11),0),IF(OR(NOT(ISNUMBER(INDEX(InverterPQ!$B$7:$L$7,1,MATCH($D$22,InverterPQ!$B$4:$L$4,1))))),0,IF($D$22=INDEX(InverterPQ!$B$4:$L$4,1,MATCH($D$22,InverterPQ!$B$4:$L$4,1)),INDEX(InverterPQ!$B$7:$L$7,1,MATCH($D$22,InverterPQ!$B$4:$L$4,1)),IF(NOT(ISNUMBER(INDEX(InverterPQ!$B$7:$L$7,1,MATCH($D$22,InverterPQ!$B$4:$L$4,1)+1))),0,INDEX(InverterPQ!$B$7:$L$7,1,MATCH($D$22,InverterPQ!$B$4:$L$4,1))+(INDEX(InverterPQ!$B$7:$L$7,1,MATCH($D$22,InverterPQ!$B$4:$L$4,1)+1)-INDEX(InverterPQ!$B$7:$L$7,1,MATCH($D$22,InverterPQ!$B$4:$L$4,1)))*($D$22-INDEX(InverterPQ!$B$4:$L$4,1,MATCH($D$22,InverterPQ!$B$4:$L$4,1)))/(INDEX(InverterPQ!$B$4:$L$4,1,MATCH($D$22,InverterPQ!$B$4:$L$4,1)+1)-INDEX(InverterPQ!$B$4:$L$4,1,MATCH($D$22,InverterPQ!$B$4:$L$4,1))))))) -> 60 | F22: =Sizing!$B$44*E22/100*Sizing!$B$32/1000+Sizing!$B$39-Sizing!$B$19 -> 33.393756 | G22: =Sizing!$B$44*E22/100*Sizing!$B$32/1000+Sizing!$B$19 -> 45.885444 | H22: =IF(A22<GridCodes!$D$15/100-0.0001,0,$B$4*IF(GridCodes!$E$15<=GridCodes!$D$15,1,MIN(1,(A22-GridCodes!$D$15/100)/(GridCodes!$E$15/100-GridCodes!$D$15/100)))) -> 0 | I22: =IF(A22<GridCodes!$D$15/100-0.0001,0,IF(GridCodes!$F$15=1,IF(A22>=0.5,$B$4,$B$4*0.12/0.33+($B$4-$B$4*0.12/0.33)*(A22-GridCodes!$D$15/100)/(0.5-GridCodes!$D$15/100)),$B$4*IF(GridCodes!$E$15<=GridCodes!$D$15,1,MIN(1,(A22-GridCodes!$D$15/100)/(GridCodes!$E$15/100-GridCodes!$D$15/100))))) -> 0 | J22: =IF(AND(MAX(0,F22)>=H22-0.001,MAX(0,G22)>=I22-0.001),"PASS","FAIL") -> PASS | K22: =-I22 -> 0 | L22: =-G22 -> -45.885444
A23: 0.05 | B23: =A23*Sizing!$B$5 -> 2.64 | C23: =A23*Sizing!$B$29*1000/Sizing!$B$44 -> 14.984176 | D23: =C23/Sizing!$B$32 -> 0.041278721 | E23: =IF($D$23>=1,IF(ISNUMBER(INDEX(InverterPQ!$B$7:$L$7,1,11)),INDEX(InverterPQ!$B$7:$L$7,1,11),0),IF(OR(NOT(ISNUMBER(INDEX(InverterPQ!$B$7:$L$7,1,MATCH($D$23,InverterPQ!$B$4:$L$4,1))))),0,IF($D$23=INDEX(InverterPQ!$B$4:$L$4,1,MATCH($D$23,InverterPQ!$B$4:$L$4,1)),INDEX(InverterPQ!$B$7:$L$7,1,MATCH($D$23,InverterPQ!$B$4:$L$4,1)),IF(NOT(ISNUMBER(INDEX(InverterPQ!$B$7:$L$7,1,MATCH($D$23,InverterPQ!$B$4:$L$4,1)+1))),0,INDEX(InverterPQ!$B$7:$L$7,1,MATCH($D$23,InverterPQ!$B$4:$L$4,1))+(INDEX(InverterPQ!$B$7:$L$7,1,MATCH($D$23,InverterPQ!$B$4:$L$4,1)+1)-INDEX(InverterPQ!$B$7:$L$7,1,MATCH($D$23,InverterPQ!$B$4:$L$4,1)))*($D$23-INDEX(InverterPQ!$B$4:$L$4,1,MATCH($D$23,InverterPQ!$B$4:$L$4,1)))/(INDEX(InverterPQ!$B$4:$L$4,1,MATCH($D$23,InverterPQ!$B$4:$L$4,1)+1)-INDEX(InverterPQ!$B$4:$L$4,1,MATCH($D$23,InverterPQ!$B$4:$L$4,1))))))) -> 60 | F23: =Sizing!$B$44*E23/100*Sizing!$B$32/1000+Sizing!$B$39-Sizing!$B$19 -> 33.393756 | G23: =Sizing!$B$44*E23/100*Sizing!$B$32/1000+Sizing!$B$19 -> 45.885444 | H23: =IF(A23<GridCodes!$D$15/100-0.0001,0,$B$4*IF(GridCodes!$E$15<=GridCodes!$D$15,1,MIN(1,(A23-GridCodes!$D$15/100)/(GridCodes!$E$15/100-GridCodes!$D$15/100)))) -> 0 | I23: =IF(A23<GridCodes!$D$15/100-0.0001,0,IF(GridCodes!$F$15=1,IF(A23>=0.5,$B$4,$B$4*0.12/0.33+($B$4-$B$4*0.12/0.33)*(A23-GridCodes!$D$15/100)/(0.5-GridCodes!$D$15/100)),$B$4*IF(GridCodes!$E$15<=GridCodes!$D$15,1,MIN(1,(A23-GridCodes!$D$15/100)/(GridCodes!$E$15/100-GridCodes!$D$15/100))))) -> 0 | J23: =IF(AND(MAX(0,F23)>=H23-0.001,MAX(0,G23)>=I23-0.001),"PASS","FAIL") -> PASS | K23: =-I23 -> 0 | L23: =-G23 -> -45.885444
A24: 0.1 | B24: =A24*Sizing!$B$5 -> 5.28 | C24: =A24*Sizing!$B$29*1000/Sizing!$B$44 -> 29.968352 | D24: =C24/Sizing!$B$32 -> 0.082557443 | E24: =IF($D$24>=1,IF(ISNUMBER(INDEX(InverterPQ!$B$7:$L$7,1,11)),INDEX(InverterPQ!$B$7:$L$7,1,11),0),IF(OR(NOT(ISNUMBER(INDEX(InverterPQ!$B$7:$L$7,1,MATCH($D$24,InverterPQ!$B$4:$L$4,1))))),0,IF($D$24=INDEX(InverterPQ!$B$4:$L$4,1,MATCH($D$24,InverterPQ!$B$4:$L$4,1)),INDEX(InverterPQ!$B$7:$L$7,1,MATCH($D$24,InverterPQ!$B$4:$L$4,1)),IF(NOT(ISNUMBER(INDEX(InverterPQ!$B$7:$L$7,1,MATCH($D$24,InverterPQ!$B$4:$L$4,1)+1))),0,INDEX(InverterPQ!$B$7:$L$7,1,MATCH($D$24,InverterPQ!$B$4:$L$4,1))+(INDEX(InverterPQ!$B$7:$L$7,1,MATCH($D$24,InverterPQ!$B$4:$L$4,1)+1)-INDEX(InverterPQ!$B$7:$L$7,1,MATCH($D$24,InverterPQ!$B$4:$L$4,1)))*($D$24-INDEX(InverterPQ!$B$4:$L$4,1,MATCH($D$24,InverterPQ!$B$4:$L$4,1)))/(INDEX(InverterPQ!$B$4:$L$4,1,MATCH($D$24,InverterPQ!$B$4:$L$4,1)+1)-INDEX(InverterPQ!$B$4:$L$4,1,MATCH($D$24,InverterPQ!$B$4:$L$4,1))))))) -> 60 | F24: =Sizing!$B$44*E24/100*Sizing!$B$32/1000+Sizing!$B$39-Sizing!$B$19 -> 33.393756 | G24: =Sizing!$B$44*E24/100*Sizing!$B$32/1000+Sizing!$B$19 -> 45.885444 | H24: =IF(A24<GridCodes!$D$15/100-0.0001,0,$B$4*IF(GridCodes!$E$15<=GridCodes!$D$15,1,MIN(1,(A24-GridCodes!$D$15/100)/(GridCodes!$E$15/100-GridCodes!$D$15/100)))) -> 0 | I24: =IF(A24<GridCodes!$D$15/100-0.0001,0,IF(GridCodes!$F$15=1,IF(A24>=0.5,$B$4,$B$4*0.12/0.33+($B$4-$B$4*0.12/0.33)*(A24-GridCodes!$D$15/100)/(0.5-GridCodes!$D$15/100)),$B$4*IF(GridCodes!$E$15<=GridCodes!$D$15,1,MIN(1,(A24-GridCodes!$D$15/100)/(GridCodes!$E$15/100-GridCodes!$D$15/100))))) -> 0 | J24: =IF(AND(MAX(0,F24)>=H24-0.001,MAX(0,G24)>=I24-0.001),"PASS","FAIL") -> PASS | K24: =-I24 -> 0 | L24: =-G24 -> -45.885444
A25: 0.15 | B25: =A25*Sizing!$B$5 -> 7.92 | C25: =A25*Sizing!$B$29*1000/Sizing!$B$44 -> 44.952527 | D25: =C25/Sizing!$B$32 -> 0.12383616 | E25: =IF($D$25>=1,IF(ISNUMBER(INDEX(InverterPQ!$B$7:$L$7,1,11)),INDEX(InverterPQ!$B$7:$L$7,1,11),0),IF(OR(NOT(ISNUMBER(INDEX(InverterPQ!$B$7:$L$7,1,MATCH($D$25,InverterPQ!$B$4:$L$4,1))))),0,IF($D$25=INDEX(InverterPQ!$B$4:$L$4,1,MATCH($D$25,InverterPQ!$B$4:$L$4,1)),INDEX(InverterPQ!$B$7:$L$7,1,MATCH($D$25,InverterPQ!$B$4:$L$4,1)),IF(NOT(ISNUMBER(INDEX(InverterPQ!$B$7:$L$7,1,MATCH($D$25,InverterPQ!$B$4:$L$4,1)+1))),0,INDEX(InverterPQ!$B$7:$L$7,1,MATCH($D$25,InverterPQ!$B$4:$L$4,1))+(INDEX(InverterPQ!$B$7:$L$7,1,MATCH($D$25,InverterPQ!$B$4:$L$4,1)+1)-INDEX(InverterPQ!$B$7:$L$7,1,MATCH($D$25,InverterPQ!$B$4:$L$4,1)))*($D$25-INDEX(InverterPQ!$B$4:$L$4,1,MATCH($D$25,InverterPQ!$B$4:$L$4,1)))/(INDEX(InverterPQ!$B$4:$L$4,1,MATCH($D$25,InverterPQ!$B$4:$L$4,1)+1)-INDEX(InverterPQ!$B$4:$L$4,1,MATCH($D$25,InverterPQ!$B$4:$L$4,1))))))) -> 60 | F25: =Sizing!$B$44*E25/100*Sizing!$B$32/1000+Sizing!$B$39-Sizing!$B$19 -> 33.393756 | G25: =Sizing!$B$44*E25/100*Sizing!$B$32/1000+Sizing!$B$19 -> 45.885444 | H25: =IF(A25<GridCodes!$D$15/100-0.0001,0,$B$4*IF(GridCodes!$E$15<=GridCodes!$D$15,1,MIN(1,(A25-GridCodes!$D$15/100)/(GridCodes!$E$15/100-GridCodes!$D$15/100)))) -> 0 | I25: =IF(A25<GridCodes!$D$15/100-0.0001,0,IF(GridCodes!$F$15=1,IF(A25>=0.5,$B$4,$B$4*0.12/0.33+($B$4-$B$4*0.12/0.33)*(A25-GridCodes!$D$15/100)/(0.5-GridCodes!$D$15/100)),$B$4*IF(GridCodes!$E$15<=GridCodes!$D$15,1,MIN(1,(A25-GridCodes!$D$15/100)/(GridCodes!$E$15/100-GridCodes!$D$15/100))))) -> 0 | J25: =IF(AND(MAX(0,F25)>=H25-0.001,MAX(0,G25)>=I25-0.001),"PASS","FAIL") -> PASS | K25: =-I25 -> 0 | L25: =-G25 -> -45.885444
A26: 0.2 | B26: =A26*Sizing!$B$5 -> 10.56 | C26: =A26*Sizing!$B$29*1000/Sizing!$B$44 -> 59.936703 | D26: =C26/Sizing!$B$32 -> 0.16511489 | E26: =IF($D$26>=1,IF(ISNUMBER(INDEX(InverterPQ!$B$7:$L$7,1,11)),INDEX(InverterPQ!$B$7:$L$7,1,11),0),IF(OR(NOT(ISNUMBER(INDEX(InverterPQ!$B$7:$L$7,1,MATCH($D$26,InverterPQ!$B$4:$L$4,1))))),0,IF($D$26=INDEX(InverterPQ!$B$4:$L$4,1,MATCH($D$26,InverterPQ!$B$4:$L$4,1)),INDEX(InverterPQ!$B$7:$L$7,1,MATCH($D$26,InverterPQ!$B$4:$L$4,1)),IF(NOT(ISNUMBER(INDEX(InverterPQ!$B$7:$L$7,1,MATCH($D$26,InverterPQ!$B$4:$L$4,1)+1))),0,INDEX(InverterPQ!$B$7:$L$7,1,MATCH($D$26,InverterPQ!$B$4:$L$4,1))+(INDEX(InverterPQ!$B$7:$L$7,1,MATCH($D$26,InverterPQ!$B$4:$L$4,1)+1)-INDEX(InverterPQ!$B$7:$L$7,1,MATCH($D$26,InverterPQ!$B$4:$L$4,1)))*($D$26-INDEX(InverterPQ!$B$4:$L$4,1,MATCH($D$26,InverterPQ!$B$4:$L$4,1)))/(INDEX(InverterPQ!$B$4:$L$4,1,MATCH($D$26,InverterPQ!$B$4:$L$4,1)+1)-INDEX(InverterPQ!$B$4:$L$4,1,MATCH($D$26,InverterPQ!$B$4:$L$4,1))))))) -> 60 | F26: =Sizing!$B$44*E26/100*Sizing!$B$32/1000+Sizing!$B$39-Sizing!$B$19 -> 33.393756 | G26: =Sizing!$B$44*E26/100*Sizing!$B$32/1000+Sizing!$B$19 -> 45.885444 | H26: =IF(A26<GridCodes!$D$15/100-0.0001,0,$B$4*IF(GridCodes!$E$15<=GridCodes!$D$15,1,MIN(1,(A26-GridCodes!$D$15/100)/(GridCodes!$E$15/100-GridCodes!$D$15/100)))) -> 17.3712 | I26: =IF(A26<GridCodes!$D$15/100-0.0001,0,IF(GridCodes!$F$15=1,IF(A26>=0.5,$B$4,$B$4*0.12/0.33+($B$4-$B$4*0.12/0.33)*(A26-GridCodes!$D$15/100)/(0.5-GridCodes!$D$15/100)),$B$4*IF(GridCodes!$E$15<=GridCodes!$D$15,1,MIN(1,(A26-GridCodes!$D$15/100)/(GridCodes!$E$15/100-GridCodes!$D$15/100))))) -> 6.3168 | J26: =IF(AND(MAX(0,F26)>=H26-0.001,MAX(0,G26)>=I26-0.001),"PASS","FAIL") -> PASS | K26: =-I26 -> -6.3168 | L26: =-G26 -> -45.885444
A27: 0.25 | B27: =A27*Sizing!$B$5 -> 13.2 | C27: =A27*Sizing!$B$29*1000/Sizing!$B$44 -> 74.920879 | D27: =C27/Sizing!$B$32 -> 0.20639361 | E27: =IF($D$27>=1,IF(ISNUMBER(INDEX(InverterPQ!$B$7:$L$7,1,11)),INDEX(InverterPQ!$B$7:$L$7,1,11),0),IF(OR(NOT(ISNUMBER(INDEX(InverterPQ!$B$7:$L$7,1,MATCH($D$27,InverterPQ!$B$4:$L$4,1))))),0,IF($D$27=INDEX(InverterPQ!$B$4:$L$4,1,MATCH($D$27,InverterPQ!$B$4:$L$4,1)),INDEX(InverterPQ!$B$7:$L$7,1,MATCH($D$27,InverterPQ!$B$4:$L$4,1)),IF(NOT(ISNUMBER(INDEX(InverterPQ!$B$7:$L$7,1,MATCH($D$27,InverterPQ!$B$4:$L$4,1)+1))),0,INDEX(InverterPQ!$B$7:$L$7,1,MATCH($D$27,InverterPQ!$B$4:$L$4,1))+(INDEX(InverterPQ!$B$7:$L$7,1,MATCH($D$27,InverterPQ!$B$4:$L$4,1)+1)-INDEX(InverterPQ!$B$7:$L$7,1,MATCH($D$27,InverterPQ!$B$4:$L$4,1)))*($D$27-INDEX(InverterPQ!$B$4:$L$4,1,MATCH($D$27,InverterPQ!$B$4:$L$4,1)))/(INDEX(InverterPQ!$B$4:$L$4,1,MATCH($D$27,InverterPQ!$B$4:$L$4,1)+1)-INDEX(InverterPQ!$B$4:$L$4,1,MATCH($D$27,InverterPQ!$B$4:$L$4,1))))))) -> 60 | F27: =Sizing!$B$44*E27/100*Sizing!$B$32/1000+Sizing!$B$39-Sizing!$B$19 -> 33.393756 | G27: =Sizing!$B$44*E27/100*Sizing!$B$32/1000+Sizing!$B$19 -> 45.885444 | H27: =IF(A27<GridCodes!$D$15/100-0.0001,0,$B$4*IF(GridCodes!$E$15<=GridCodes!$D$15,1,MIN(1,(A27-GridCodes!$D$15/100)/(GridCodes!$E$15/100-GridCodes!$D$15/100)))) -> 17.3712 | I27: =IF(A27<GridCodes!$D$15/100-0.0001,0,IF(GridCodes!$F$15=1,IF(A27>=0.5,$B$4,$B$4*0.12/0.33+($B$4-$B$4*0.12/0.33)*(A27-GridCodes!$D$15/100)/(0.5-GridCodes!$D$15/100)),$B$4*IF(GridCodes!$E$15<=GridCodes!$D$15,1,MIN(1,(A27-GridCodes!$D$15/100)/(GridCodes!$E$15/100-GridCodes!$D$15/100))))) -> 8.1592 | J27: =IF(AND(MAX(0,F27)>=H27-0.001,MAX(0,G27)>=I27-0.001),"PASS","FAIL") -> PASS | K27: =-I27 -> -8.1592 | L27: =-G27 -> -45.885444
A28: 0.3 | B28: =A28*Sizing!$B$5 -> 15.84 | C28: =A28*Sizing!$B$29*1000/Sizing!$B$44 -> 89.905055 | D28: =C28/Sizing!$B$32 -> 0.24767233 | E28: =IF($D$28>=1,IF(ISNUMBER(INDEX(InverterPQ!$B$7:$L$7,1,11)),INDEX(InverterPQ!$B$7:$L$7,1,11),0),IF(OR(NOT(ISNUMBER(INDEX(InverterPQ!$B$7:$L$7,1,MATCH($D$28,InverterPQ!$B$4:$L$4,1))))),0,IF($D$28=INDEX(InverterPQ!$B$4:$L$4,1,MATCH($D$28,InverterPQ!$B$4:$L$4,1)),INDEX(InverterPQ!$B$7:$L$7,1,MATCH($D$28,InverterPQ!$B$4:$L$4,1)),IF(NOT(ISNUMBER(INDEX(InverterPQ!$B$7:$L$7,1,MATCH($D$28,InverterPQ!$B$4:$L$4,1)+1))),0,INDEX(InverterPQ!$B$7:$L$7,1,MATCH($D$28,InverterPQ!$B$4:$L$4,1))+(INDEX(InverterPQ!$B$7:$L$7,1,MATCH($D$28,InverterPQ!$B$4:$L$4,1)+1)-INDEX(InverterPQ!$B$7:$L$7,1,MATCH($D$28,InverterPQ!$B$4:$L$4,1)))*($D$28-INDEX(InverterPQ!$B$4:$L$4,1,MATCH($D$28,InverterPQ!$B$4:$L$4,1)))/(INDEX(InverterPQ!$B$4:$L$4,1,MATCH($D$28,InverterPQ!$B$4:$L$4,1)+1)-INDEX(InverterPQ!$B$4:$L$4,1,MATCH($D$28,InverterPQ!$B$4:$L$4,1))))))) -> 60 | F28: =Sizing!$B$44*E28/100*Sizing!$B$32/1000+Sizing!$B$39-Sizing!$B$19 -> 33.393756 | G28: =Sizing!$B$44*E28/100*Sizing!$B$32/1000+Sizing!$B$19 -> 45.885444 | H28: =IF(A28<GridCodes!$D$15/100-0.0001,0,$B$4*IF(GridCodes!$E$15<=GridCodes!$D$15,1,MIN(1,(A28-GridCodes!$D$15/100)/(GridCodes!$E$15/100-GridCodes!$D$15/100)))) -> 17.3712 | I28: =IF(A28<GridCodes!$D$15/100-0.0001,0,IF(GridCodes!$F$15=1,IF(A28>=0.5,$B$4,$B$4*0.12/0.33+($B$4-$B$4*0.12/0.33)*(A28-GridCodes!$D$15/100)/(0.5-GridCodes!$D$15/100)),$B$4*IF(GridCodes!$E$15<=GridCodes!$D$15,1,MIN(1,(A28-GridCodes!$D$15/100)/(GridCodes!$E$15/100-GridCodes!$D$15/100))))) -> 10.0016 | J28: =IF(AND(MAX(0,F28)>=H28-0.001,MAX(0,G28)>=I28-0.001),"PASS","FAIL") -> PASS | K28: =-I28 -> -10.0016 | L28: =-G28 -> -45.885444
A29: 0.35 | B29: =A29*Sizing!$B$5 -> 18.48 | C29: =A29*Sizing!$B$29*1000/Sizing!$B$44 -> 104.88923 | D29: =C29/Sizing!$B$32 -> 0.28895105 | E29: =IF($D$29>=1,IF(ISNUMBER(INDEX(InverterPQ!$B$7:$L$7,1,11)),INDEX(InverterPQ!$B$7:$L$7,1,11),0),IF(OR(NOT(ISNUMBER(INDEX(InverterPQ!$B$7:$L$7,1,MATCH($D$29,InverterPQ!$B$4:$L$4,1))))),0,IF($D$29=INDEX(InverterPQ!$B$4:$L$4,1,MATCH($D$29,InverterPQ!$B$4:$L$4,1)),INDEX(InverterPQ!$B$7:$L$7,1,MATCH($D$29,InverterPQ!$B$4:$L$4,1)),IF(NOT(ISNUMBER(INDEX(InverterPQ!$B$7:$L$7,1,MATCH($D$29,InverterPQ!$B$4:$L$4,1)+1))),0,INDEX(InverterPQ!$B$7:$L$7,1,MATCH($D$29,InverterPQ!$B$4:$L$4,1))+(INDEX(InverterPQ!$B$7:$L$7,1,MATCH($D$29,InverterPQ!$B$4:$L$4,1)+1)-INDEX(InverterPQ!$B$7:$L$7,1,MATCH($D$29,InverterPQ!$B$4:$L$4,1)))*($D$29-INDEX(InverterPQ!$B$4:$L$4,1,MATCH($D$29,InverterPQ!$B$4:$L$4,1)))/(INDEX(InverterPQ!$B$4:$L$4,1,MATCH($D$29,InverterPQ!$B$4:$L$4,1)+1)-INDEX(InverterPQ!$B$4:$L$4,1,MATCH($D$29,InverterPQ!$B$4:$L$4,1))))))) -> 60 | F29: =Sizing!$B$44*E29/100*Sizing!$B$32/1000+Sizing!$B$39-Sizing!$B$19 -> 33.393756 | G29: =Sizing!$B$44*E29/100*Sizing!$B$32/1000+Sizing!$B$19 -> 45.885444 | H29: =IF(A29<GridCodes!$D$15/100-0.0001,0,$B$4*IF(GridCodes!$E$15<=GridCodes!$D$15,1,MIN(1,(A29-GridCodes!$D$15/100)/(GridCodes!$E$15/100-GridCodes!$D$15/100)))) -> 17.3712 | I29: =IF(A29<GridCodes!$D$15/100-0.0001,0,IF(GridCodes!$F$15=1,IF(A29>=0.5,$B$4,$B$4*0.12/0.33+($B$4-$B$4*0.12/0.33)*(A29-GridCodes!$D$15/100)/(0.5-GridCodes!$D$15/100)),$B$4*IF(GridCodes!$E$15<=GridCodes!$D$15,1,MIN(1,(A29-GridCodes!$D$15/100)/(GridCodes!$E$15/100-GridCodes!$D$15/100))))) -> 11.844 | J29: =IF(AND(MAX(0,F29)>=H29-0.001,MAX(0,G29)>=I29-0.001),"PASS","FAIL") -> PASS | K29: =-I29 -> -11.844 | L29: =-G29 -> -45.885444
A30: 0.4 | B30: =A30*Sizing!$B$5 -> 21.12 | C30: =A30*Sizing!$B$29*1000/Sizing!$B$44 -> 119.87341 | D30: =C30/Sizing!$B$32 -> 0.33022977 | E30: =IF($D$30>=1,IF(ISNUMBER(INDEX(InverterPQ!$B$7:$L$7,1,11)),INDEX(InverterPQ!$B$7:$L$7,1,11),0),IF(OR(NOT(ISNUMBER(INDEX(InverterPQ!$B$7:$L$7,1,MATCH($D$30,InverterPQ!$B$4:$L$4,1))))),0,IF($D$30=INDEX(InverterPQ!$B$4:$L$4,1,MATCH($D$30,InverterPQ!$B$4:$L$4,1)),INDEX(InverterPQ!$B$7:$L$7,1,MATCH($D$30,InverterPQ!$B$4:$L$4,1)),IF(NOT(ISNUMBER(INDEX(InverterPQ!$B$7:$L$7,1,MATCH($D$30,InverterPQ!$B$4:$L$4,1)+1))),0,INDEX(InverterPQ!$B$7:$L$7,1,MATCH($D$30,InverterPQ!$B$4:$L$4,1))+(INDEX(InverterPQ!$B$7:$L$7,1,MATCH($D$30,InverterPQ!$B$4:$L$4,1)+1)-INDEX(InverterPQ!$B$7:$L$7,1,MATCH($D$30,InverterPQ!$B$4:$L$4,1)))*($D$30-INDEX(InverterPQ!$B$4:$L$4,1,MATCH($D$30,InverterPQ!$B$4:$L$4,1)))/(INDEX(InverterPQ!$B$4:$L$4,1,MATCH($D$30,InverterPQ!$B$4:$L$4,1)+1)-INDEX(InverterPQ!$B$4:$L$4,1,MATCH($D$30,InverterPQ!$B$4:$L$4,1))))))) -> 60 | F30: =Sizing!$B$44*E30/100*Sizing!$B$32/1000+Sizing!$B$39-Sizing!$B$19 -> 33.393756 | G30: =Sizing!$B$44*E30/100*Sizing!$B$32/1000+Sizing!$B$19 -> 45.885444 | H30: =IF(A30<GridCodes!$D$15/100-0.0001,0,$B$4*IF(GridCodes!$E$15<=GridCodes!$D$15,1,MIN(1,(A30-GridCodes!$D$15/100)/(GridCodes!$E$15/100-GridCodes!$D$15/100)))) -> 17.3712 | I30: =IF(A30<GridCodes!$D$15/100-0.0001,0,IF(GridCodes!$F$15=1,IF(A30>=0.5,$B$4,$B$4*0.12/0.33+($B$4-$B$4*0.12/0.33)*(A30-GridCodes!$D$15/100)/(0.5-GridCodes!$D$15/100)),$B$4*IF(GridCodes!$E$15<=GridCodes!$D$15,1,MIN(1,(A30-GridCodes!$D$15/100)/(GridCodes!$E$15/100-GridCodes!$D$15/100))))) -> 13.6864 | J30: =IF(AND(MAX(0,F30)>=H30-0.001,MAX(0,G30)>=I30-0.001),"PASS","FAIL") -> PASS | K30: =-I30 -> -13.6864 | L30: =-G30 -> -45.885444
A31: 0.45 | B31: =A31*Sizing!$B$5 -> 23.76 | C31: =A31*Sizing!$B$29*1000/Sizing!$B$44 -> 134.85758 | D31: =C31/Sizing!$B$32 -> 0.37150849 | E31: =IF($D$31>=1,IF(ISNUMBER(INDEX(InverterPQ!$B$7:$L$7,1,11)),INDEX(InverterPQ!$B$7:$L$7,1,11),0),IF(OR(NOT(ISNUMBER(INDEX(InverterPQ!$B$7:$L$7,1,MATCH($D$31,InverterPQ!$B$4:$L$4,1))))),0,IF($D$31=INDEX(InverterPQ!$B$4:$L$4,1,MATCH($D$31,InverterPQ!$B$4:$L$4,1)),INDEX(InverterPQ!$B$7:$L$7,1,MATCH($D$31,InverterPQ!$B$4:$L$4,1)),IF(NOT(ISNUMBER(INDEX(InverterPQ!$B$7:$L$7,1,MATCH($D$31,InverterPQ!$B$4:$L$4,1)+1))),0,INDEX(InverterPQ!$B$7:$L$7,1,MATCH($D$31,InverterPQ!$B$4:$L$4,1))+(INDEX(InverterPQ!$B$7:$L$7,1,MATCH($D$31,InverterPQ!$B$4:$L$4,1)+1)-INDEX(InverterPQ!$B$7:$L$7,1,MATCH($D$31,InverterPQ!$B$4:$L$4,1)))*($D$31-INDEX(InverterPQ!$B$4:$L$4,1,MATCH($D$31,InverterPQ!$B$4:$L$4,1)))/(INDEX(InverterPQ!$B$4:$L$4,1,MATCH($D$31,InverterPQ!$B$4:$L$4,1)+1)-INDEX(InverterPQ!$B$4:$L$4,1,MATCH($D$31,InverterPQ!$B$4:$L$4,1))))))) -> 60 | F31: =Sizing!$B$44*E31/100*Sizing!$B$32/1000+Sizing!$B$39-Sizing!$B$19 -> 33.393756 | G31: =Sizing!$B$44*E31/100*Sizing!$B$32/1000+Sizing!$B$19 -> 45.885444 | H31: =IF(A31<GridCodes!$D$15/100-0.0001,0,$B$4*IF(GridCodes!$E$15<=GridCodes!$D$15,1,MIN(1,(A31-GridCodes!$D$15/100)/(GridCodes!$E$15/100-GridCodes!$D$15/100)))) -> 17.3712 | I31: =IF(A31<GridCodes!$D$15/100-0.0001,0,IF(GridCodes!$F$15=1,IF(A31>=0.5,$B$4,$B$4*0.12/0.33+($B$4-$B$4*0.12/0.33)*(A31-GridCodes!$D$15/100)/(0.5-GridCodes!$D$15/100)),$B$4*IF(GridCodes!$E$15<=GridCodes!$D$15,1,MIN(1,(A31-GridCodes!$D$15/100)/(GridCodes!$E$15/100-GridCodes!$D$15/100))))) -> 15.5288 | J31: =IF(AND(MAX(0,F31)>=H31-0.001,MAX(0,G31)>=I31-0.001),"PASS","FAIL") -> PASS | K31: =-I31 -> -15.5288 | L31: =-G31 -> -45.885444
A32: 0.5 | B32: =A32*Sizing!$B$5 -> 26.4 | C32: =A32*Sizing!$B$29*1000/Sizing!$B$44 -> 149.84176 | D32: =C32/Sizing!$B$32 -> 0.41278721 | E32: =IF($D$32>=1,IF(ISNUMBER(INDEX(InverterPQ!$B$7:$L$7,1,11)),INDEX(InverterPQ!$B$7:$L$7,1,11),0),IF(OR(NOT(ISNUMBER(INDEX(InverterPQ!$B$7:$L$7,1,MATCH($D$32,InverterPQ!$B$4:$L$4,1))))),0,IF($D$32=INDEX(InverterPQ!$B$4:$L$4,1,MATCH($D$32,InverterPQ!$B$4:$L$4,1)),INDEX(InverterPQ!$B$7:$L$7,1,MATCH($D$32,InverterPQ!$B$4:$L$4,1)),IF(NOT(ISNUMBER(INDEX(InverterPQ!$B$7:$L$7,1,MATCH($D$32,InverterPQ!$B$4:$L$4,1)+1))),0,INDEX(InverterPQ!$B$7:$L$7,1,MATCH($D$32,InverterPQ!$B$4:$L$4,1))+(INDEX(InverterPQ!$B$7:$L$7,1,MATCH($D$32,InverterPQ!$B$4:$L$4,1)+1)-INDEX(InverterPQ!$B$7:$L$7,1,MATCH($D$32,InverterPQ!$B$4:$L$4,1)))*($D$32-INDEX(InverterPQ!$B$4:$L$4,1,MATCH($D$32,InverterPQ!$B$4:$L$4,1)))/(INDEX(InverterPQ!$B$4:$L$4,1,MATCH($D$32,InverterPQ!$B$4:$L$4,1)+1)-INDEX(InverterPQ!$B$4:$L$4,1,MATCH($D$32,InverterPQ!$B$4:$L$4,1))))))) -> 60 | F32: =Sizing!$B$44*E32/100*Sizing!$B$32/1000+Sizing!$B$39-Sizing!$B$19 -> 33.393756 | G32: =Sizing!$B$44*E32/100*Sizing!$B$32/1000+Sizing!$B$19 -> 45.885444 | H32: =IF(A32<GridCodes!$D$15/100-0.0001,0,$B$4*IF(GridCodes!$E$15<=GridCodes!$D$15,1,MIN(1,(A32-GridCodes!$D$15/100)/(GridCodes!$E$15/100-GridCodes!$D$15/100)))) -> 17.3712 | I32: =IF(A32<GridCodes!$D$15/100-0.0001,0,IF(GridCodes!$F$15=1,IF(A32>=0.5,$B$4,$B$4*0.12/0.33+($B$4-$B$4*0.12/0.33)*(A32-GridCodes!$D$15/100)/(0.5-GridCodes!$D$15/100)),$B$4*IF(GridCodes!$E$15<=GridCodes!$D$15,1,MIN(1,(A32-GridCodes!$D$15/100)/(GridCodes!$E$15/100-GridCodes!$D$15/100))))) -> 17.3712 | J32: =IF(AND(MAX(0,F32)>=H32-0.001,MAX(0,G32)>=I32-0.001),"PASS","FAIL") -> PASS | K32: =-I32 -> -17.3712 | L32: =-G32 -> -45.885444
A33: 0.55 | B33: =A33*Sizing!$B$5 -> 29.04 | C33: =A33*Sizing!$B$29*1000/Sizing!$B$44 -> 164.82593 | D33: =C33/Sizing!$B$32 -> 0.45406593 | E33: =IF($D$33>=1,IF(ISNUMBER(INDEX(InverterPQ!$B$7:$L$7,1,11)),INDEX(InverterPQ!$B$7:$L$7,1,11),0),IF(OR(NOT(ISNUMBER(INDEX(InverterPQ!$B$7:$L$7,1,MATCH($D$33,InverterPQ!$B$4:$L$4,1))))),0,IF($D$33=INDEX(InverterPQ!$B$4:$L$4,1,MATCH($D$33,InverterPQ!$B$4:$L$4,1)),INDEX(InverterPQ!$B$7:$L$7,1,MATCH($D$33,InverterPQ!$B$4:$L$4,1)),IF(NOT(ISNUMBER(INDEX(InverterPQ!$B$7:$L$7,1,MATCH($D$33,InverterPQ!$B$4:$L$4,1)+1))),0,INDEX(InverterPQ!$B$7:$L$7,1,MATCH($D$33,InverterPQ!$B$4:$L$4,1))+(INDEX(InverterPQ!$B$7:$L$7,1,MATCH($D$33,InverterPQ!$B$4:$L$4,1)+1)-INDEX(InverterPQ!$B$7:$L$7,1,MATCH($D$33,InverterPQ!$B$4:$L$4,1)))*($D$33-INDEX(InverterPQ!$B$4:$L$4,1,MATCH($D$33,InverterPQ!$B$4:$L$4,1)))/(INDEX(InverterPQ!$B$4:$L$4,1,MATCH($D$33,InverterPQ!$B$4:$L$4,1)+1)-INDEX(InverterPQ!$B$4:$L$4,1,MATCH($D$33,InverterPQ!$B$4:$L$4,1))))))) -> 60 | F33: =Sizing!$B$44*E33/100*Sizing!$B$32/1000+Sizing!$B$39-Sizing!$B$19 -> 33.393756 | G33: =Sizing!$B$44*E33/100*Sizing!$B$32/1000+Sizing!$B$19 -> 45.885444 | H33: =IF(A33<GridCodes!$D$15/100-0.0001,0,$B$4*IF(GridCodes!$E$15<=GridCodes!$D$15,1,MIN(1,(A33-GridCodes!$D$15/100)/(GridCodes!$E$15/100-GridCodes!$D$15/100)))) -> 17.3712 | I33: =IF(A33<GridCodes!$D$15/100-0.0001,0,IF(GridCodes!$F$15=1,IF(A33>=0.5,$B$4,$B$4*0.12/0.33+($B$4-$B$4*0.12/0.33)*(A33-GridCodes!$D$15/100)/(0.5-GridCodes!$D$15/100)),$B$4*IF(GridCodes!$E$15<=GridCodes!$D$15,1,MIN(1,(A33-GridCodes!$D$15/100)/(GridCodes!$E$15/100-GridCodes!$D$15/100))))) -> 17.3712 | J33: =IF(AND(MAX(0,F33)>=H33-0.001,MAX(0,G33)>=I33-0.001),"PASS","FAIL") -> PASS | K33: =-I33 -> -17.3712 | L33: =-G33 -> -45.885444
A34: 0.6 | B34: =A34*Sizing!$B$5 -> 31.68 | C34: =A34*Sizing!$B$29*1000/Sizing!$B$44 -> 179.81011 | D34: =C34/Sizing!$B$32 -> 0.49534466 | E34: =IF($D$34>=1,IF(ISNUMBER(INDEX(InverterPQ!$B$7:$L$7,1,11)),INDEX(InverterPQ!$B$7:$L$7,1,11),0),IF(OR(NOT(ISNUMBER(INDEX(InverterPQ!$B$7:$L$7,1,MATCH($D$34,InverterPQ!$B$4:$L$4,1))))),0,IF($D$34=INDEX(InverterPQ!$B$4:$L$4,1,MATCH($D$34,InverterPQ!$B$4:$L$4,1)),INDEX(InverterPQ!$B$7:$L$7,1,MATCH($D$34,InverterPQ!$B$4:$L$4,1)),IF(NOT(ISNUMBER(INDEX(InverterPQ!$B$7:$L$7,1,MATCH($D$34,InverterPQ!$B$4:$L$4,1)+1))),0,INDEX(InverterPQ!$B$7:$L$7,1,MATCH($D$34,InverterPQ!$B$4:$L$4,1))+(INDEX(InverterPQ!$B$7:$L$7,1,MATCH($D$34,InverterPQ!$B$4:$L$4,1)+1)-INDEX(InverterPQ!$B$7:$L$7,1,MATCH($D$34,InverterPQ!$B$4:$L$4,1)))*($D$34-INDEX(InverterPQ!$B$4:$L$4,1,MATCH($D$34,InverterPQ!$B$4:$L$4,1)))/(INDEX(InverterPQ!$B$4:$L$4,1,MATCH($D$34,InverterPQ!$B$4:$L$4,1)+1)-INDEX(InverterPQ!$B$4:$L$4,1,MATCH($D$34,InverterPQ!$B$4:$L$4,1))))))) -> 60 | F34: =Sizing!$B$44*E34/100*Sizing!$B$32/1000+Sizing!$B$39-Sizing!$B$19 -> 33.393756 | G34: =Sizing!$B$44*E34/100*Sizing!$B$32/1000+Sizing!$B$19 -> 45.885444 | H34: =IF(A34<GridCodes!$D$15/100-0.0001,0,$B$4*IF(GridCodes!$E$15<=GridCodes!$D$15,1,MIN(1,(A34-GridCodes!$D$15/100)/(GridCodes!$E$15/100-GridCodes!$D$15/100)))) -> 17.3712 | I34: =IF(A34<GridCodes!$D$15/100-0.0001,0,IF(GridCodes!$F$15=1,IF(A34>=0.5,$B$4,$B$4*0.12/0.33+($B$4-$B$4*0.12/0.33)*(A34-GridCodes!$D$15/100)/(0.5-GridCodes!$D$15/100)),$B$4*IF(GridCodes!$E$15<=GridCodes!$D$15,1,MIN(1,(A34-GridCodes!$D$15/100)/(GridCodes!$E$15/100-GridCodes!$D$15/100))))) -> 17.3712 | J34: =IF(AND(MAX(0,F34)>=H34-0.001,MAX(0,G34)>=I34-0.001),"PASS","FAIL") -> PASS | K34: =-I34 -> -17.3712 | L34: =-G34 -> -45.885444
A35: 0.65 | B35: =A35*Sizing!$B$5 -> 34.32 | C35: =A35*Sizing!$B$29*1000/Sizing!$B$44 -> 194.79429 | D35: =C35/Sizing!$B$32 -> 0.53662338 | E35: =IF($D$35>=1,IF(ISNUMBER(INDEX(InverterPQ!$B$7:$L$7,1,11)),INDEX(InverterPQ!$B$7:$L$7,1,11),0),IF(OR(NOT(ISNUMBER(INDEX(InverterPQ!$B$7:$L$7,1,MATCH($D$35,InverterPQ!$B$4:$L$4,1))))),0,IF($D$35=INDEX(InverterPQ!$B$4:$L$4,1,MATCH($D$35,InverterPQ!$B$4:$L$4,1)),INDEX(InverterPQ!$B$7:$L$7,1,MATCH($D$35,InverterPQ!$B$4:$L$4,1)),IF(NOT(ISNUMBER(INDEX(InverterPQ!$B$7:$L$7,1,MATCH($D$35,InverterPQ!$B$4:$L$4,1)+1))),0,INDEX(InverterPQ!$B$7:$L$7,1,MATCH($D$35,InverterPQ!$B$4:$L$4,1))+(INDEX(InverterPQ!$B$7:$L$7,1,MATCH($D$35,InverterPQ!$B$4:$L$4,1)+1)-INDEX(InverterPQ!$B$7:$L$7,1,MATCH($D$35,InverterPQ!$B$4:$L$4,1)))*($D$35-INDEX(InverterPQ!$B$4:$L$4,1,MATCH($D$35,InverterPQ!$B$4:$L$4,1)))/(INDEX(InverterPQ!$B$4:$L$4,1,MATCH($D$35,InverterPQ!$B$4:$L$4,1)+1)-INDEX(InverterPQ!$B$4:$L$4,1,MATCH($D$35,InverterPQ!$B$4:$L$4,1))))))) -> 60 | F35: =Sizing!$B$44*E35/100*Sizing!$B$32/1000+Sizing!$B$39-Sizing!$B$19 -> 33.393756 | G35: =Sizing!$B$44*E35/100*Sizing!$B$32/1000+Sizing!$B$19 -> 45.885444 | H35: =IF(A35<GridCodes!$D$15/100-0.0001,0,$B$4*IF(GridCodes!$E$15<=GridCodes!$D$15,1,MIN(1,(A35-GridCodes!$D$15/100)/(GridCodes!$E$15/100-GridCodes!$D$15/100)))) -> 17.3712 | I35: =IF(A35<GridCodes!$D$15/100-0.0001,0,IF(GridCodes!$F$15=1,IF(A35>=0.5,$B$4,$B$4*0.12/0.33+($B$4-$B$4*0.12/0.33)*(A35-GridCodes!$D$15/100)/(0.5-GridCodes!$D$15/100)),$B$4*IF(GridCodes!$E$15<=GridCodes!$D$15,1,MIN(1,(A35-GridCodes!$D$15/100)/(GridCodes!$E$15/100-GridCodes!$D$15/100))))) -> 17.3712 | J35: =IF(AND(MAX(0,F35)>=H35-0.001,MAX(0,G35)>=I35-0.001),"PASS","FAIL") -> PASS | K35: =-I35 -> -17.3712 | L35: =-G35 -> -45.885444
A36: 0.7 | B36: =A36*Sizing!$B$5 -> 36.96 | C36: =A36*Sizing!$B$29*1000/Sizing!$B$44 -> 209.77846 | D36: =C36/Sizing!$B$32 -> 0.5779021 | E36: =IF($D$36>=1,IF(ISNUMBER(INDEX(InverterPQ!$B$7:$L$7,1,11)),INDEX(InverterPQ!$B$7:$L$7,1,11),0),IF(OR(NOT(ISNUMBER(INDEX(InverterPQ!$B$7:$L$7,1,MATCH($D$36,InverterPQ!$B$4:$L$4,1))))),0,IF($D$36=INDEX(InverterPQ!$B$4:$L$4,1,MATCH($D$36,InverterPQ!$B$4:$L$4,1)),INDEX(InverterPQ!$B$7:$L$7,1,MATCH($D$36,InverterPQ!$B$4:$L$4,1)),IF(NOT(ISNUMBER(INDEX(InverterPQ!$B$7:$L$7,1,MATCH($D$36,InverterPQ!$B$4:$L$4,1)+1))),0,INDEX(InverterPQ!$B$7:$L$7,1,MATCH($D$36,InverterPQ!$B$4:$L$4,1))+(INDEX(InverterPQ!$B$7:$L$7,1,MATCH($D$36,InverterPQ!$B$4:$L$4,1)+1)-INDEX(InverterPQ!$B$7:$L$7,1,MATCH($D$36,InverterPQ!$B$4:$L$4,1)))*($D$36-INDEX(InverterPQ!$B$4:$L$4,1,MATCH($D$36,InverterPQ!$B$4:$L$4,1)))/(INDEX(InverterPQ!$B$4:$L$4,1,MATCH($D$36,InverterPQ!$B$4:$L$4,1)+1)-INDEX(InverterPQ!$B$4:$L$4,1,MATCH($D$36,InverterPQ!$B$4:$L$4,1))))))) -> 60 | F36: =Sizing!$B$44*E36/100*Sizing!$B$32/1000+Sizing!$B$39-Sizing!$B$19 -> 33.393756 | G36: =Sizing!$B$44*E36/100*Sizing!$B$32/1000+Sizing!$B$19 -> 45.885444 | H36: =IF(A36<GridCodes!$D$15/100-0.0001,0,$B$4*IF(GridCodes!$E$15<=GridCodes!$D$15,1,MIN(1,(A36-GridCodes!$D$15/100)/(GridCodes!$E$15/100-GridCodes!$D$15/100)))) -> 17.3712 | I36: =IF(A36<GridCodes!$D$15/100-0.0001,0,IF(GridCodes!$F$15=1,IF(A36>=0.5,$B$4,$B$4*0.12/0.33+($B$4-$B$4*0.12/0.33)*(A36-GridCodes!$D$15/100)/(0.5-GridCodes!$D$15/100)),$B$4*IF(GridCodes!$E$15<=GridCodes!$D$15,1,MIN(1,(A36-GridCodes!$D$15/100)/(GridCodes!$E$15/100-GridCodes!$D$15/100))))) -> 17.3712 | J36: =IF(AND(MAX(0,F36)>=H36-0.001,MAX(0,G36)>=I36-0.001),"PASS","FAIL") -> PASS | K36: =-I36 -> -17.3712 | L36: =-G36 -> -45.885444
A37: 0.75 | B37: =A37*Sizing!$B$5 -> 39.6 | C37: =A37*Sizing!$B$29*1000/Sizing!$B$44 -> 224.76264 | D37: =C37/Sizing!$B$32 -> 0.61918082 | E37: =IF($D$37>=1,IF(ISNUMBER(INDEX(InverterPQ!$B$7:$L$7,1,11)),INDEX(InverterPQ!$B$7:$L$7,1,11),0),IF(OR(NOT(ISNUMBER(INDEX(InverterPQ!$B$7:$L$7,1,MATCH($D$37,InverterPQ!$B$4:$L$4,1))))),0,IF($D$37=INDEX(InverterPQ!$B$4:$L$4,1,MATCH($D$37,InverterPQ!$B$4:$L$4,1)),INDEX(InverterPQ!$B$7:$L$7,1,MATCH($D$37,InverterPQ!$B$4:$L$4,1)),IF(NOT(ISNUMBER(INDEX(InverterPQ!$B$7:$L$7,1,MATCH($D$37,InverterPQ!$B$4:$L$4,1)+1))),0,INDEX(InverterPQ!$B$7:$L$7,1,MATCH($D$37,InverterPQ!$B$4:$L$4,1))+(INDEX(InverterPQ!$B$7:$L$7,1,MATCH($D$37,InverterPQ!$B$4:$L$4,1)+1)-INDEX(InverterPQ!$B$7:$L$7,1,MATCH($D$37,InverterPQ!$B$4:$L$4,1)))*($D$37-INDEX(InverterPQ!$B$4:$L$4,1,MATCH($D$37,InverterPQ!$B$4:$L$4,1)))/(INDEX(InverterPQ!$B$4:$L$4,1,MATCH($D$37,InverterPQ!$B$4:$L$4,1)+1)-INDEX(InverterPQ!$B$4:$L$4,1,MATCH($D$37,InverterPQ!$B$4:$L$4,1))))))) -> 60 | F37: =Sizing!$B$44*E37/100*Sizing!$B$32/1000+Sizing!$B$39-Sizing!$B$19 -> 33.393756 | G37: =Sizing!$B$44*E37/100*Sizing!$B$32/1000+Sizing!$B$19 -> 45.885444 | H37: =IF(A37<GridCodes!$D$15/100-0.0001,0,$B$4*IF(GridCodes!$E$15<=GridCodes!$D$15,1,MIN(1,(A37-GridCodes!$D$15/100)/(GridCodes!$E$15/100-GridCodes!$D$15/100)))) -> 17.3712 | I37: =IF(A37<GridCodes!$D$15/100-0.0001,0,IF(GridCodes!$F$15=1,IF(A37>=0.5,$B$4,$B$4*0.12/0.33+($B$4-$B$4*0.12/0.33)*(A37-GridCodes!$D$15/100)/(0.5-GridCodes!$D$15/100)),$B$4*IF(GridCodes!$E$15<=GridCodes!$D$15,1,MIN(1,(A37-GridCodes!$D$15/100)/(GridCodes!$E$15/100-GridCodes!$D$15/100))))) -> 17.3712 | J37: =IF(AND(MAX(0,F37)>=H37-0.001,MAX(0,G37)>=I37-0.001),"PASS","FAIL") -> PASS | K37: =-I37 -> -17.3712 | L37: =-G37 -> -45.885444
A38: 0.8 | B38: =A38*Sizing!$B$5 -> 42.24 | C38: =A38*Sizing!$B$29*1000/Sizing!$B$44 -> 239.74681 | D38: =C38/Sizing!$B$32 -> 0.66045954 | E38: =IF($D$38>=1,IF(ISNUMBER(INDEX(InverterPQ!$B$7:$L$7,1,11)),INDEX(InverterPQ!$B$7:$L$7,1,11),0),IF(OR(NOT(ISNUMBER(INDEX(InverterPQ!$B$7:$L$7,1,MATCH($D$38,InverterPQ!$B$4:$L$4,1))))),0,IF($D$38=INDEX(InverterPQ!$B$4:$L$4,1,MATCH($D$38,InverterPQ!$B$4:$L$4,1)),INDEX(InverterPQ!$B$7:$L$7,1,MATCH($D$38,InverterPQ!$B$4:$L$4,1)),IF(NOT(ISNUMBER(INDEX(InverterPQ!$B$7:$L$7,1,MATCH($D$38,InverterPQ!$B$4:$L$4,1)+1))),0,INDEX(InverterPQ!$B$7:$L$7,1,MATCH($D$38,InverterPQ!$B$4:$L$4,1))+(INDEX(InverterPQ!$B$7:$L$7,1,MATCH($D$38,InverterPQ!$B$4:$L$4,1)+1)-INDEX(InverterPQ!$B$7:$L$7,1,MATCH($D$38,InverterPQ!$B$4:$L$4,1)))*($D$38-INDEX(InverterPQ!$B$4:$L$4,1,MATCH($D$38,InverterPQ!$B$4:$L$4,1)))/(INDEX(InverterPQ!$B$4:$L$4,1,MATCH($D$38,InverterPQ!$B$4:$L$4,1)+1)-INDEX(InverterPQ!$B$4:$L$4,1,MATCH($D$38,InverterPQ!$B$4:$L$4,1))))))) -> 60 | F38: =Sizing!$B$44*E38/100*Sizing!$B$32/1000+Sizing!$B$39-Sizing!$B$19 -> 33.393756 | G38: =Sizing!$B$44*E38/100*Sizing!$B$32/1000+Sizing!$B$19 -> 45.885444 | H38: =IF(A38<GridCodes!$D$15/100-0.0001,0,$B$4*IF(GridCodes!$E$15<=GridCodes!$D$15,1,MIN(1,(A38-GridCodes!$D$15/100)/(GridCodes!$E$15/100-GridCodes!$D$15/100)))) -> 17.3712 | I38: =IF(A38<GridCodes!$D$15/100-0.0001,0,IF(GridCodes!$F$15=1,IF(A38>=0.5,$B$4,$B$4*0.12/0.33+($B$4-$B$4*0.12/0.33)*(A38-GridCodes!$D$15/100)/(0.5-GridCodes!$D$15/100)),$B$4*IF(GridCodes!$E$15<=GridCodes!$D$15,1,MIN(1,(A38-GridCodes!$D$15/100)/(GridCodes!$E$15/100-GridCodes!$D$15/100))))) -> 17.3712 | J38: =IF(AND(MAX(0,F38)>=H38-0.001,MAX(0,G38)>=I38-0.001),"PASS","FAIL") -> PASS | K38: =-I38 -> -17.3712 | L38: =-G38 -> -45.885444
A39: 0.85 | B39: =A39*Sizing!$B$5 -> 44.88 | C39: =A39*Sizing!$B$29*1000/Sizing!$B$44 -> 254.73099 | D39: =C39/Sizing!$B$32 -> 0.70173826 | E39: =IF($D$39>=1,IF(ISNUMBER(INDEX(InverterPQ!$B$7:$L$7,1,11)),INDEX(InverterPQ!$B$7:$L$7,1,11),0),IF(OR(NOT(ISNUMBER(INDEX(InverterPQ!$B$7:$L$7,1,MATCH($D$39,InverterPQ!$B$4:$L$4,1))))),0,IF($D$39=INDEX(InverterPQ!$B$4:$L$4,1,MATCH($D$39,InverterPQ!$B$4:$L$4,1)),INDEX(InverterPQ!$B$7:$L$7,1,MATCH($D$39,InverterPQ!$B$4:$L$4,1)),IF(NOT(ISNUMBER(INDEX(InverterPQ!$B$7:$L$7,1,MATCH($D$39,InverterPQ!$B$4:$L$4,1)+1))),0,INDEX(InverterPQ!$B$7:$L$7,1,MATCH($D$39,InverterPQ!$B$4:$L$4,1))+(INDEX(InverterPQ!$B$7:$L$7,1,MATCH($D$39,InverterPQ!$B$4:$L$4,1)+1)-INDEX(InverterPQ!$B$7:$L$7,1,MATCH($D$39,InverterPQ!$B$4:$L$4,1)))*($D$39-INDEX(InverterPQ!$B$4:$L$4,1,MATCH($D$39,InverterPQ!$B$4:$L$4,1)))/(INDEX(InverterPQ!$B$4:$L$4,1,MATCH($D$39,InverterPQ!$B$4:$L$4,1)+1)-INDEX(InverterPQ!$B$4:$L$4,1,MATCH($D$39,InverterPQ!$B$4:$L$4,1))))))) -> 60 | F39: =Sizing!$B$44*E39/100*Sizing!$B$32/1000+Sizing!$B$39-Sizing!$B$19 -> 33.393756 | G39: =Sizing!$B$44*E39/100*Sizing!$B$32/1000+Sizing!$B$19 -> 45.885444 | H39: =IF(A39<GridCodes!$D$15/100-0.0001,0,$B$4*IF(GridCodes!$E$15<=GridCodes!$D$15,1,MIN(1,(A39-GridCodes!$D$15/100)/(GridCodes!$E$15/100-GridCodes!$D$15/100)))) -> 17.3712 | I39: =IF(A39<GridCodes!$D$15/100-0.0001,0,IF(GridCodes!$F$15=1,IF(A39>=0.5,$B$4,$B$4*0.12/0.33+($B$4-$B$4*0.12/0.33)*(A39-GridCodes!$D$15/100)/(0.5-GridCodes!$D$15/100)),$B$4*IF(GridCodes!$E$15<=GridCodes!$D$15,1,MIN(1,(A39-GridCodes!$D$15/100)/(GridCodes!$E$15/100-GridCodes!$D$15/100))))) -> 17.3712 | J39: =IF(AND(MAX(0,F39)>=H39-0.001,MAX(0,G39)>=I39-0.001),"PASS","FAIL") -> PASS | K39: =-I39 -> -17.3712 | L39: =-G39 -> -45.885444
A40: 0.9 | B40: =A40*Sizing!$B$5 -> 47.52 | C40: =A40*Sizing!$B$29*1000/Sizing!$B$44 -> 269.71516 | D40: =C40/Sizing!$B$32 -> 0.74301698 | E40: =IF($D$40>=1,IF(ISNUMBER(INDEX(InverterPQ!$B$7:$L$7,1,11)),INDEX(InverterPQ!$B$7:$L$7,1,11),0),IF(OR(NOT(ISNUMBER(INDEX(InverterPQ!$B$7:$L$7,1,MATCH($D$40,InverterPQ!$B$4:$L$4,1))))),0,IF($D$40=INDEX(InverterPQ!$B$4:$L$4,1,MATCH($D$40,InverterPQ!$B$4:$L$4,1)),INDEX(InverterPQ!$B$7:$L$7,1,MATCH($D$40,InverterPQ!$B$4:$L$4,1)),IF(NOT(ISNUMBER(INDEX(InverterPQ!$B$7:$L$7,1,MATCH($D$40,InverterPQ!$B$4:$L$4,1)+1))),0,INDEX(InverterPQ!$B$7:$L$7,1,MATCH($D$40,InverterPQ!$B$4:$L$4,1))+(INDEX(InverterPQ!$B$7:$L$7,1,MATCH($D$40,InverterPQ!$B$4:$L$4,1)+1)-INDEX(InverterPQ!$B$7:$L$7,1,MATCH($D$40,InverterPQ!$B$4:$L$4,1)))*($D$40-INDEX(InverterPQ!$B$4:$L$4,1,MATCH($D$40,InverterPQ!$B$4:$L$4,1)))/(INDEX(InverterPQ!$B$4:$L$4,1,MATCH($D$40,InverterPQ!$B$4:$L$4,1)+1)-INDEX(InverterPQ!$B$4:$L$4,1,MATCH($D$40,InverterPQ!$B$4:$L$4,1))))))) -> 60 | F40: =Sizing!$B$44*E40/100*Sizing!$B$32/1000+Sizing!$B$39-Sizing!$B$19 -> 33.393756 | G40: =Sizing!$B$44*E40/100*Sizing!$B$32/1000+Sizing!$B$19 -> 45.885444 | H40: =IF(A40<GridCodes!$D$15/100-0.0001,0,$B$4*IF(GridCodes!$E$15<=GridCodes!$D$15,1,MIN(1,(A40-GridCodes!$D$15/100)/(GridCodes!$E$15/100-GridCodes!$D$15/100)))) -> 17.3712 | I40: =IF(A40<GridCodes!$D$15/100-0.0001,0,IF(GridCodes!$F$15=1,IF(A40>=0.5,$B$4,$B$4*0.12/0.33+($B$4-$B$4*0.12/0.33)*(A40-GridCodes!$D$15/100)/(0.5-GridCodes!$D$15/100)),$B$4*IF(GridCodes!$E$15<=GridCodes!$D$15,1,MIN(1,(A40-GridCodes!$D$15/100)/(GridCodes!$E$15/100-GridCodes!$D$15/100))))) -> 17.3712 | J40: =IF(AND(MAX(0,F40)>=H40-0.001,MAX(0,G40)>=I40-0.001),"PASS","FAIL") -> PASS | K40: =-I40 -> -17.3712 | L40: =-G40 -> -45.885444
A41: 0.95 | B41: =A41*Sizing!$B$5 -> 50.16 | C41: =A41*Sizing!$B$29*1000/Sizing!$B$44 -> 284.69934 | D41: =C41/Sizing!$B$32 -> 0.7842957 | E41: =IF($D$41>=1,IF(ISNUMBER(INDEX(InverterPQ!$B$7:$L$7,1,11)),INDEX(InverterPQ!$B$7:$L$7,1,11),0),IF(OR(NOT(ISNUMBER(INDEX(InverterPQ!$B$7:$L$7,1,MATCH($D$41,InverterPQ!$B$4:$L$4,1))))),0,IF($D$41=INDEX(InverterPQ!$B$4:$L$4,1,MATCH($D$41,InverterPQ!$B$4:$L$4,1)),INDEX(InverterPQ!$B$7:$L$7,1,MATCH($D$41,InverterPQ!$B$4:$L$4,1)),IF(NOT(ISNUMBER(INDEX(InverterPQ!$B$7:$L$7,1,MATCH($D$41,InverterPQ!$B$4:$L$4,1)+1))),0,INDEX(InverterPQ!$B$7:$L$7,1,MATCH($D$41,InverterPQ!$B$4:$L$4,1))+(INDEX(InverterPQ!$B$7:$L$7,1,MATCH($D$41,InverterPQ!$B$4:$L$4,1)+1)-INDEX(InverterPQ!$B$7:$L$7,1,MATCH($D$41,InverterPQ!$B$4:$L$4,1)))*($D$41-INDEX(InverterPQ!$B$4:$L$4,1,MATCH($D$41,InverterPQ!$B$4:$L$4,1)))/(INDEX(InverterPQ!$B$4:$L$4,1,MATCH($D$41,InverterPQ!$B$4:$L$4,1)+1)-INDEX(InverterPQ!$B$4:$L$4,1,MATCH($D$41,InverterPQ!$B$4:$L$4,1))))))) -> 60 | F41: =Sizing!$B$44*E41/100*Sizing!$B$32/1000+Sizing!$B$39-Sizing!$B$19 -> 33.393756 | G41: =Sizing!$B$44*E41/100*Sizing!$B$32/1000+Sizing!$B$19 -> 45.885444 | H41: =IF(A41<GridCodes!$D$15/100-0.0001,0,$B$4*IF(GridCodes!$E$15<=GridCodes!$D$15,1,MIN(1,(A41-GridCodes!$D$15/100)/(GridCodes!$E$15/100-GridCodes!$D$15/100)))) -> 17.3712 | I41: =IF(A41<GridCodes!$D$15/100-0.0001,0,IF(GridCodes!$F$15=1,IF(A41>=0.5,$B$4,$B$4*0.12/0.33+($B$4-$B$4*0.12/0.33)*(A41-GridCodes!$D$15/100)/(0.5-GridCodes!$D$15/100)),$B$4*IF(GridCodes!$E$15<=GridCodes!$D$15,1,MIN(1,(A41-GridCodes!$D$15/100)/(GridCodes!$E$15/100-GridCodes!$D$15/100))))) -> 17.3712 | J41: =IF(AND(MAX(0,F41)>=H41-0.001,MAX(0,G41)>=I41-0.001),"PASS","FAIL") -> PASS | K41: =-I41 -> -17.3712 | L41: =-G41 -> -45.885444
A42: 1 | B42: =A42*Sizing!$B$5 -> 52.8 | C42: =A42*Sizing!$B$29*1000/Sizing!$B$44 -> 299.68352 | D42: =C42/Sizing!$B$32 -> 0.82557443 | E42: =IF($D$42>=1,IF(ISNUMBER(INDEX(InverterPQ!$B$7:$L$7,1,11)),INDEX(InverterPQ!$B$7:$L$7,1,11),0),IF(OR(NOT(ISNUMBER(INDEX(InverterPQ!$B$7:$L$7,1,MATCH($D$42,InverterPQ!$B$4:$L$4,1))))),0,IF($D$42=INDEX(InverterPQ!$B$4:$L$4,1,MATCH($D$42,InverterPQ!$B$4:$L$4,1)),INDEX(InverterPQ!$B$7:$L$7,1,MATCH($D$42,InverterPQ!$B$4:$L$4,1)),IF(NOT(ISNUMBER(INDEX(InverterPQ!$B$7:$L$7,1,MATCH($D$42,InverterPQ!$B$4:$L$4,1)+1))),0,INDEX(InverterPQ!$B$7:$L$7,1,MATCH($D$42,InverterPQ!$B$4:$L$4,1))+(INDEX(InverterPQ!$B$7:$L$7,1,MATCH($D$42,InverterPQ!$B$4:$L$4,1)+1)-INDEX(InverterPQ!$B$7:$L$7,1,MATCH($D$42,InverterPQ!$B$4:$L$4,1)))*($D$42-INDEX(InverterPQ!$B$4:$L$4,1,MATCH($D$42,InverterPQ!$B$4:$L$4,1)))/(INDEX(InverterPQ!$B$4:$L$4,1,MATCH($D$42,InverterPQ!$B$4:$L$4,1)+1)-INDEX(InverterPQ!$B$4:$L$4,1,MATCH($D$42,InverterPQ!$B$4:$L$4,1))))))) -> 55.805794 | F42: =Sizing!$B$44*E42/100*Sizing!$B$32/1000+Sizing!$B$39-Sizing!$B$19 -> 30.622812 | G42: =Sizing!$B$44*E42/100*Sizing!$B$32/1000+Sizing!$B$19 -> 43.1145 | H42: =IF(A42<GridCodes!$D$15/100-0.0001,0,$B$4*IF(GridCodes!$E$15<=GridCodes!$D$15,1,MIN(1,(A42-GridCodes!$D$15/100)/(GridCodes!$E$15/100-GridCodes!$D$15/100)))) -> 17.3712 | I42: =IF(A42<GridCodes!$D$15/100-0.0001,0,IF(GridCodes!$F$15=1,IF(A42>=0.5,$B$4,$B$4*0.12/0.33+($B$4-$B$4*0.12/0.33)*(A42-GridCodes!$D$15/100)/(0.5-GridCodes!$D$15/100)),$B$4*IF(GridCodes!$E$15<=GridCodes!$D$15,1,MIN(1,(A42-GridCodes!$D$15/100)/(GridCodes!$E$15/100-GridCodes!$D$15/100))))) -> 17.3712 | J42: =IF(AND(MAX(0,F42)>=H42-0.001,MAX(0,G42)>=I42-0.001),"PASS","FAIL") -> PASS | K42: =-I42 -> -17.3712 | L42: =-G42 -> -43.1145
A44: OVERALL VERDICT | B44: =IF(COUNTIF(G8:G13,"FAIL")+COUNTIF(J22:J42,"FAIL")=0,"COMPLIANT","NOT COMPLIANT") -> COMPLIANT
